Workbook

Sheet 说明
A1: XBRAIN_V6 功能测试用例（收敛用）
A2: 用途 | B2: 按 00 应用需求文档逐条列出测试项，按 F1-F14 功能类分 sheet，测试人按行填写结果，汇总页自动统计收敛进度。
A3: 测试项来源 | B3: docs/00-应用需求文档.md §3-§17 中所有带编号的需求行（同号取首次出现；已作废原文 -X 行与整条作废行不列）。功能类与需求前缀对应：F1=NAV F2=VOI F3=PAY F4=PER F5=TSK F6=EVT F7=COM F8=HMI F9=AI F10=FLT F11=CHG F12=BIT F13=CAL+CFG F14=CMD；非功能 NFR 放附表。RT/CON/GL 为架构约束，不作测试项。
A4: 生成时间 | B4: 2026-10-29（依据机器人仓库当时的 00 册；00 改动后需重新生成或手工增删行）
A5: 需要填写的列（黄色） | B5: 测试结果 / 备注 / 测试人 / 测试时间。其余列为生成内容，可按实际细化「测试方法」。
A6: 测试结果取值 | B6: 通过 · 失败 · 阻塞（前置条件不具备，如未接线 / 缺硬件）· 不适用（需求已作废或本期不做）· 留空 = 未测
A7: 备注写什么 | B7: 测试过程（如何触发、观察到什么、关键日志 / 回执）；失败或阻塞时写原因与复现步骤；关联提交号或缺陷卡片。
A8: 现状评估（2026-10-29） | B8: ✅ 真机实测过 · 🟡 已实现，仅单测/仿真或真机未验 · ❌ 设计了未实现或未接线 · 未核：本次评估没找到证据。这是开发侧在 2026-10-29 的评估，供排期参考，不等于测试结论。
A9: 测试方法说明 | B9: 每类给出默认方法（初稿），部分行写了具体方法；执行前按需求描述中的量化指标细化判据。
A10: 预填结果 | B10: 标了结果的几行是 2026-10-28/29 本会话在机器人上实测通过的项（测试人：Claude（AI）+ 现场工程师），可复核后保留或改写。
A12: 示例行（格式参考）
A13: 测试类 | B13: 需求编号 | C13: 测试功能 | D13: 测试方法 | E13: 测试结果 | F13: 备注 | G13: 测试人 | H13: 测试时间
A14: F2 语音交互 / 4.7 D 模式 | B14: VOI-60 | C14: 喇叭为独占资源，统一仲裁 | D14: D 期间发一条 tts_local，观察是否插播 | E14: 通过 | F14: D 期间发 tts_local，回执 E_BUSY（speaker held by alarm_d），现场无插播 | G14: 张三 | H14: 2026-10-29 16:00

Sheet 汇总
A1: 功能类 | B1: 测试项数 | C1: 通过 | D1: 失败 | E1: 阻塞 | F1: 不适用 | G1: 未测 | H1: 已测完成率 | I1: 通过率
A2: F1 导航与运动 | B2: =COUNTA('F1 导航与运动'!$C$2:$C$106) -> 105 | C2: =COUNTIF('F1 导航与运动'!$G$2:$G$106,"通过") -> 0 | D2: =COUNTIF('F1 导航与运动'!$G$2:$G$106,"失败") -> 0 | E2: =COUNTIF('F1 导航与运动'!$G$2:$G$106,"阻塞") -> 0 | F2: =COUNTIF('F1 导航与运动'!$G$2:$G$106,"不适用") -> 0 | G2: =B2-C2-D2-E2-F2 -> 105 | H2: =IF(B2-F2=0,0,(C2+D2+E2)/(B2-F2)) -> 0 | I2: =IF(C2+D2=0,0,C2/(C2+D2)) -> 0
A3: F2 语音交互 | B3: =COUNTA('F2 语音交互'!$C$2:$C$39) -> 38 | C3: =COUNTIF('F2 语音交互'!$G$2:$G$39,"通过") -> 5 | D3: =COUNTIF('F2 语音交互'!$G$2:$G$39,"失败") -> 0 | E3: =COUNTIF('F2 语音交互'!$G$2:$G$39,"阻塞") -> 0 | F3: =COUNTIF('F2 语音交互'!$G$2:$G$39,"不适用") -> 0 | G3: =B3-C3-D3-E3-F3 -> 33 | H3: =IF(B3-F3=0,0,(C3+D3+E3)/(B3-F3)) -> 0.13157895 | I3: =IF(C3+D3=0,0,C3/(C3+D3)) -> 1
A4: F3 载荷控制 | B4: =COUNTA('F3 载荷控制'!$C$2:$C$39) -> 38 | C4: =COUNTIF('F3 载荷控制'!$G$2:$G$39,"通过") -> 1 | D4: =COUNTIF('F3 载荷控制'!$G$2:$G$39,"失败") -> 0 | E4: =COUNTIF('F3 载荷控制'!$G$2:$G$39,"阻塞") -> 0 | F4: =COUNTIF('F3 载荷控制'!$G$2:$G$39,"不适用") -> 0 | G4: =B4-C4-D4-E4-F4 -> 37 | H4: =IF(B4-F4=0,0,(C4+D4+E4)/(B4-F4)) -> 0.026315789 | I4: =IF(C4+D4=0,0,C4/(C4+D4)) -> 1
A5: F4 环境感知 | B5: =COUNTA('F4 环境感知'!$C$2:$C$32) -> 31 | C5: =COUNTIF('F4 环境感知'!$G$2:$G$32,"通过") -> 0 | D5: =COUNTIF('F4 环境感知'!$G$2:$G$32,"失败") -> 0 | E5: =COUNTIF('F4 环境感知'!$G$2:$G$32,"阻塞") -> 0 | F5: =COUNTIF('F4 环境感知'!$G$2:$G$32,"不适用") -> 0 | G5: =B5-C5-D5-E5-F5 -> 31 | H5: =IF(B5-F5=0,0,(C5+D5+E5)/(B5-F5)) -> 0 | I5: =IF(C5+D5=0,0,C5/(C5+D5)) -> 0
A6: F5 任务系统 | B6: =COUNTA('F5 任务系统'!$C$2:$C$19) -> 18 | C6: =COUNTIF('F5 任务系统'!$G$2:$G$19,"通过") -> 0 | D6: =COUNTIF('F5 任务系统'!$G$2:$G$19,"失败") -> 0 | E6: =COUNTIF('F5 任务系统'!$G$2:$G$19,"阻塞") -> 0 | F6: =COUNTIF('F5 任务系统'!$G$2:$G$19,"不适用") -> 0 | G6: =B6-C6-D6-E6-F6 -> 18 | H6: =IF(B6-F6=0,0,(C6+D6+E6)/(B6-F6)) -> 0 | I6: =IF(C6+D6=0,0,C6/(C6+D6)) -> 0
A7: F6 事件系统 | B7: =COUNTA('F6 事件系统'!$C$2:$C$11) -> 10 | C7: =COUNTIF('F6 事件系统'!$G$2:$G$11,"通过") -> 1 | D7: =COUNTIF('F6 事件系统'!$G$2:$G$11,"失败") -> 0 | E7: =COUNTIF('F6 事件系统'!$G$2:$G$11,"阻塞") -> 0 | F7: =COUNTIF('F6 事件系统'!$G$2:$G$11,"不适用") -> 0 | G7: =B7-C7-D7-E7-F7 -> 9 | H7: =IF(B7-F7=0,0,(C7+D7+E7)/(B7-F7)) -> 0.1 | I7: =IF(C7+D7=0,0,C7/(C7+D7)) -> 1
A8: F7 通信 | B8: =COUNTA('F7 通信'!$C$2:$C$29) -> 28 | C8: =COUNTIF('F7 通信'!$G$2:$G$29,"通过") -> 0 | D8: =COUNTIF('F7 通信'!$G$2:$G$29,"失败") -> 0 | E8: =COUNTIF('F7 通信'!$G$2:$G$29,"阻塞") -> 0 | F8: =COUNTIF('F7 通信'!$G$2:$G$29,"不适用") -> 0 | G8: =B8-C8-D8-E8-F8 -> 28 | H8: =IF(B8-F8=0,0,(C8+D8+E8)/(B8-F8)) -> 0 | I8: =IF(C8+D8=0,0,C8/(C8+D8)) -> 0
A9: F8 人机界面 | B9: =COUNTA('F8 人机界面'!$C$2:$C$14) -> 13 | C9: =COUNTIF('F8 人机界面'!$G$2:$G$14,"通过") -> 0 | D9: =COUNTIF('F8 人机界面'!$G$2:$G$14,"失败") -> 0 | E9: =COUNTIF('F8 人机界面'!$G$2:$G$14,"阻塞") -> 0 | F9: =COUNTIF('F8 人机界面'!$G$2:$G$14,"不适用") -> 0 | G9: =B9-C9-D9-E9-F9 -> 13 | H9: =IF(B9-F9=0,0,(C9+D9+E9)/(B9-F9)) -> 0 | I9: =IF(C9+D9=0,0,C9/(C9+D9)) -> 0
A10: F9 AI与Agent | B10: =COUNTA('F9 AI与Agent'!$C$2:$C$43) -> 42 | C10: =COUNTIF('F9 AI与Agent'!$G$2:$G$43,"通过") -> 0 | D10: =COUNTIF('F9 AI与Agent'!$G$2:$G$43,"失败") -> 0 | E10: =COUNTIF('F9 AI与Agent'!$G$2:$G$43,"阻塞") -> 0 | F10: =COUNTIF('F9 AI与Agent'!$G$2:$G$43,"不适用") -> 0 | G10: =B10-C10-D10-E10-F10 -> 42 | H10: =IF(B10-F10=0,0,(C10+D10+E10)/(B10-F10)) -> 0 | I10: =IF(C10+D10=0,0,C10/(C10+D10)) -> 0
A11: F10 多机 | B11: =COUNTA('F10 多机'!$C$2:$C$6) -> 5 | C11: =COUNTIF('F10 多机'!$G$2:$G$6,"通过") -> 0 | D11: =COUNTIF('F10 多机'!$G$2:$G$6,"失败") -> 0 | E11: =COUNTIF('F10 多机'!$G$2:$G$6,"阻塞") -> 0 | F11: =COUNTIF('F10 多机'!$G$2:$G$6,"不适用") -> 0 | G11: =B11-C11-D11-E11-F11 -> 5 | H11: =IF(B11-F11=0,0,(C11+D11+E11)/(B11-F11)) -> 0 | I11: =IF(C11+D11=0,0,C11/(C11+D11)) -> 0
A12: F11 充电与续航 | B12: =COUNTA('F11 充电与续航'!$C$2:$C$27) -> 26 | C12: =COUNTIF('F11 充电与续航'!$G$2:$G$27,"通过") -> 0 | D12: =COUNTIF('F11 充电与续航'!$G$2:$G$27,"失败") -> 0 | E12: =COUNTIF('F11 充电与续航'!$G$2:$G$27,"阻塞") -> 0 | F12: =COUNTIF('F11 充电与续航'!$G$2:$G$27,"不适用") -> 0 | G12: =B12-C12-D12-E12-F12 -> 26 | H12: =IF(B12-F12=0,0,(C12+D12+E12)/(B12-F12)) -> 0 | I12: =IF(C12+D12=0,0,C12/(C12+D12)) -> 0
A13: F12 开机自检与健康度 | B13: =COUNTA('F12 开机自检与健康度'!$C$2:$C$19) -> 18 | C13: =COUNTIF('F12 开机自检与健康度'!$G$2:$G$19,"通过") -> 0 | D13: =COUNTIF('F12 开机自检与健康度'!$G$2:$G$19,"失败") -> 0 | E13: =COUNTIF('F12 开机自检与健康度'!$G$2:$G$19,"阻塞") -> 0 | F13: =COUNTIF('F12 开机自检与健康度'!$G$2:$G$19,"不适用") -> 0 | G13: =B13-C13-D13-E13-F13 -> 18 | H13: =IF(B13-F13=0,0,(C13+D13+E13)/(B13-F13)) -> 0 | I13: =IF(C13+D13=0,0,C13/(C13+D13)) -> 0
A14: F13 工程支撑 | B14: =COUNTA('F13 工程支撑'!$C$2:$C$24) -> 23 | C14: =COUNTIF('F13 工程支撑'!$G$2:$G$24,"通过") -> 0 | D14: =COUNTIF('F13 工程支撑'!$G$2:$G$24,"失败") -> 0 | E14: =COUNTIF('F13 工程支撑'!$G$2:$G$24,"阻塞") -> 0 | F14: =COUNTIF('F13 工程支撑'!$G$2:$G$24,"不适用") -> 0 | G14: =B14-C14-D14-E14-F14 -> 23 | H14: =IF(B14-F14=0,0,(C14+D14+E14)/(B14-F14)) -> 0 | I14: =IF(C14+D14=0,0,C14/(C14+D14)) -> 0
A15: F14 语音文本指令集 | B15: =COUNTA('F14 语音文本指令集'!$C$2:$C$44) -> 43 | C15: =COUNTIF('F14 语音文本指令集'!$G$2:$G$44,"通过") -> 0 | D15: =COUNTIF('F14 语音文本指令集'!$G$2:$G$44,"失败") -> 0 | E15: =COUNTIF('F14 语音文本指令集'!$G$2:$G$44,"阻塞") -> 0 | F15: =COUNTIF('F14 语音文本指令集'!$G$2:$G$44,"不适用") -> 0 | G15: =B15-C15-D15-E15-F15 -> 43 | H15: =IF(B15-F15=0,0,(C15+D15+E15)/(B15-F15)) -> 0 | I15: =IF(C15+D15=0,0,C15/(C15+D15)) -> 0
A16: 附-NFR 非功能 | B16: =COUNTA('附-NFR 非功能'!$C$2:$C$23) -> 22 | C16: =COUNTIF('附-NFR 非功能'!$G$2:$G$23,"通过") -> 0 | D16: =COUNTIF('附-NFR 非功能'!$G$2:$G$23,"失败") -> 0 | E16: =COUNTIF('附-NFR 非功能'!$G$2:$G$23,"阻塞") -> 0 | F16: =COUNTIF('附-NFR 非功能'!$G$2:$G$23,"不适用") -> 0 | G16: =B16-C16-D16-E16-F16 -> 22 | H16: =IF(B16-F16=0,0,(C16+D16+E16)/(B16-F16)) -> 0 | I16: =IF(C16+D16=0,0,C16/(C16+D16)) -> 0
A17: 合计 | B17: =SUM(B2:B16) -> 460 | C17: =SUM(C2:C16) -> 7 | D17: =SUM(D2:D16) -> 0 | E17: =SUM(E2:E16) -> 0 | F17: =SUM(F2:F16) -> 0 | G17: =SUM(G2:G16) -> 453 | H17: =IF(B17-F17=0,0,(C17+D17+E17)/(B17-F17)) -> 0.015217391 | I17: =IF(C17+D17=0,0,C17/(C17+D17)) -> 1
A19: 口径 | B19: 已测完成率 =（通过+失败+阻塞）/（测试项数-不适用）；通过率 = 通过 /（通过+失败）。未测 = 测试结果留空。统计随各 sheet 的「测试结果」列自动更新。

Sheet F1 导航与运动
A1: 序号 | B1: 测试类 | C1: 需求编号 | D1: 测试功能 | E1: 需求描述（摘自 00） | F1: 测试方法 | G1: 测试结果 | H1: 备注 | I1: 测试人 | J1: 测试时间 | K1: 现状评估（2026-10-29）
A2: 1 | B2: F1 / 3.1 定位 | C2: NAV-01 | D2: 系统以 RTK GPS 作为主定位源，提供 20 Hz 的实时位置与航向数据 | E2: 系统以 RTK GPS 作为主定位源，提供 20 Hz 的实时位置与航向数据 | F2: 【仿真+真机】先在 SIL（scripts/sil）复现场景跑台架；真机在有人值守、场地净空条件下验证，记录 p1 日志与 state/arb/motion、rt/motion/cmd_vel。 | K2: 🟡 rtk_driver 在收串口数据，但 state/robot 的 gps 为 fix:none，真机未定上位
A3: 2 | B3: F1 / 3.1 定位 | C3: NAV-02 | D3: RTK 解算质量（固定解 / 浮点解 / 单点解 / 失锁）必须真实反映在数据的状态位与协方差中，不得填充固定值 | E3: RTK 解算质量（固定解 / 浮点解 / 单点解 / 失锁）必须真实反映在数据的状态位与协方差中，不得填充固定值 | F3: 【仿真+真机】先在 SIL（scripts/sil）复现场景跑台架；真机在有人值守、场地净空条件下验证，记录 p1 日志与 state/arb/motion、rt/motion/cmd_vel。 | K3: 🟡 rtk_driver 在收串口数据，但 state/robot 的 gps 为 fix:none，真机未定上位
A4: 3 | B4: F1 / 3.1 定位 | C4: NAV-03 | D4: RTK 降级时导航行为必须分级降级 | E4: 正式需求（ 原【建议】·§0.4a① 结账 2026-07-31） RTK 降级时导航行为必须分级降级：固定解→正常；浮点解→减速 + 加大避障裕度；单点解/失锁→停车或低速沿最后可信路径返回 | F4: 【仿真+真机】先在 SIL（scripts/sil）复现场景跑台架；真机在有人值守、场地净空条件下验证，记录 p1 日志与 state/arb/motion、rt/motion/cmd_vel。 | K4: 🟡 rtk_driver 在收串口数据，但 state/robot 的 gps 为 fix:none，真机未定上位
A5: 4 | B5: F1 / 3.1 定位 | C5: NAV-04 | D5: 待确认 | E5: 待确认：/gnss/heading 是双天线直接测向还是单天线运动推算。若为后者，静止与低速时航向不可信，起步、原地转向、点位停留后重新出发均需特殊处理 | F5: 【仿真+真机】先在 SIL（scripts/sil）复现场景跑台架；真机在有人值守、场地净空条件下验证，记录 p1 日志与 state/arb/motion、rt/motion/cmd_vel。 | K5: 🟡 rtk_driver 在收串口数据，但 state/robot 的 gps 为 fix:none，真机未定上位
A6: 5 | B6: F1 / 3.1 定位 | C6: NAV-05 | D6: RTK 时间可作为全系统授时源，用于对齐事件时间戳、媒体文件与云端记录 | E6: 正式需求（ 原【建议】·§0.4a① 结账 2026-07-31） RTK 时间可作为全系统授时源，用于对齐事件时间戳、媒体文件与云端记录 | F6: 【仿真+真机】先在 SIL（scripts/sil）复现场景跑台架；真机在有人值守、场地净空条件下验证，记录 p1 日志与 state/arb/motion、rt/motion/cmd_vel。 | K6: 🟡 rtk_driver 在收串口数据，但 state/robot 的 gps 为 fix:none，真机未定上位
A7: 6 | B7: F1 / 3.1 定位 | C7: NAV-06 | D7: RTK 位置不确定度不可忽略 | E7: 正式需求（ 原【建议】·§0.4a① 结账 2026-07-31） RTK 位置不确定度不可忽略： 按 U54 后的 patrol 上限 2.0 m/s 重算 —— 20 Hz 定位间隔为 0.10 m，叠加 RTK 解算延迟（通常 10–50 ms，对应 0.02–0.10 m），位置误差在 0.10–0.20 m 量级。电子围栏边界判定必须计入该不确定度。 已随 U54 作废（5 m/s 不在需求内）。 注意：量级变小不等于可以忽略 —— 围栏裁剪的裕度仍须显式带这一项，见 NAV-46 | F7: 【仿真+真机】先在 SIL（scripts/sil）复现场景跑台架；真机在有人值守、场地净空条件下验证，记录 p1 日志与 state/arb/motion、rt/motion/cmd_vel。 | K7: 🟡 rtk_driver 在收串口数据，但 state/robot 的 gps 为 fix:none，真机未定上位
A8: 7 | B8: F1 / 3.2 点到点导航 | C8: NAV-10 | D8: 支持从当前位置导航至指定 RTK 位置点 | E8: 支持从当前位置导航至指定 RTK 位置点 | F8: 【仿真+真机】先在 SIL（scripts/sil）复现场景跑台架；真机在有人值守、场地净空条件下验证，记录 p1 日志与 state/arb/motion、rt/motion/cmd_vel。 | K8: 🟡 仅 SIL / 开发栈 E2E（位姿桩）；真机未跑：p3 任务执行器未接线
A9: 8 | B9: F1 / 3.2 点到点导航 | C9: NAV-11 | D9: 位置点由 WGS84 经纬度（及可选高程）定义 | E9: 位置点由 WGS84 经纬度（及可选高程）定义 | F9: 【仿真+真机】先在 SIL（scripts/sil）复现场景跑台架；真机在有人值守、场地净空条件下验证，记录 p1 日志与 state/arb/motion、rt/motion/cmd_vel。 | K9: 🟡 仅 SIL / 开发栈 E2E（位姿桩）；真机未跑：p3 任务执行器未接线
A10: 9 | B10: F1 / 3.2 点到点导航 | C10: NAV-12 | D10: 到点判定阈值可配置 具体数值待定 | E10: 到点判定阈值可配置 具体数值待定 | F10: 【仿真+真机】先在 SIL（scripts/sil）复现场景跑台架；真机在有人值守、场地净空条件下验证，记录 p1 日志与 state/arb/motion、rt/motion/cmd_vel。 | K10: 🟡 仅 SIL / 开发栈 E2E（位姿桩）；真机未跑：p3 任务执行器未接线
A11: 10 | B11: F1 / 3.2 点到点导航 | C11: NAV-13 | D11: 导航过程中全程执行反应式避障与电子围栏约束 | E11: 导航过程中全程执行反应式避障与电子围栏约束 | F11: 【仿真+真机】先在 SIL（scripts/sil）复现场景跑台架；真机在有人值守、场地净空条件下验证，记录 p1 日志与 state/arb/motion、rt/motion/cmd_vel。 | K11: 🟡 仅 SIL / 开发栈 E2E（位姿桩）；真机未跑：p3 任务执行器未接线
A12: 11 | B12: F1 / 3.3 路径导航 | C12: NAV-20 | D12: 支持由多个 RTK 位置点构成的任意长度路径的连续导航 | E12: 支持由多个 RTK 位置点构成的任意长度路径的连续导航 | F12: 【仿真+真机】先在 SIL（scripts/sil）复现场景跑台架；真机在有人值守、场地净空条件下验证，记录 p1 日志与 state/arb/motion、rt/motion/cmd_vel。 | K12: 🟡 仅 SIL / 开发栈 E2E；真机未跑
A13: 12 | B13: F1 / 3.3 路径导航 | C13: NAV-21 | D13: 路径为稠密位置点序列，机器人按序通过 | E13: 路径为稠密位置点序列，机器人按序通过 | F13: 【仿真+真机】先在 SIL（scripts/sil）复现场景跑台架；真机在有人值守、场地净空条件下验证，记录 p1 日志与 state/arb/motion、rt/motion/cmd_vel。 | K13: 🟡 仅 SIL / 开发栈 E2E；真机未跑
... A106: 105 | B106: F1 / 3.8 速度与制动（U54 订正） | C106: NAV-71 | D106: 巡逻巡航速度 3–5 m/s 作废 → 拆为 NAV-70a（无障碍 1.0–2.0）/ NAV-70b（有障碍 0.2… | E106: 巡逻巡航速度 3–5 m/s 作废 → 拆为 NAV-70a（无障碍 1.0–2.0）/ NAV-70b（有障碍 0.2–0.5） 主会话已合入 | F106: 【仿真+真机】先在 SIL（scripts/sil）复现场景跑台架；真机在有人值守、场地净空条件下验证，记录 p1 日志与 state/arb/motion、rt/motion/cmd_vel。 | K106: 🟡 速度门 / 限幅 / 旋转许可有代码与单测，真机未验

Sheet F2 语音交互
A1: 序号 | B1: 测试类 | C1: 需求编号 | D1: 测试功能 | E1: 需求描述（摘自 00） | F1: 测试方法 | G1: 测试结果 | H1: 备注 | I1: 测试人 | J1: 测试时间 | K1: 现状评估（2026-10-29）
A2: 1 | B2: F2 / 4.2 模式关系规则 | C2: VOI-01 | D2: A / B / D 互斥，且为抢占式互斥（非显式切换） | E2: A / B / D 互斥，且为抢占式互斥（非显式切换） | F2: 【真机】按模式进出路径用本地语音 / commx 文本 / 云端 Qt 触发，核对 state/mode、cmd/mode/ack、喇叭与麦克风门控（state/audio）、payload /status 与现场听感。 | K2: 🟡 B<->D 同锁换源有单测与变异体；真机做过 idle<->B、idle<->D
A3: 2 | B3: F2 / 4.2 模式关系规则 | C3: VOI-02 | D3: A / C / E 并存（三个通道常驻），但同一时刻只有一个会话有效 | E3: A / C / E 并存（三个通道常驻），但同一时刻只有一个会话有效 | F3: 【真机】按模式进出路径用本地语音 / commx 文本 / 云端 Qt 触发，核对 state/mode、cmd/mode/ack、喇叭与麦克风门控（state/audio）、payload /status 与现场听感。 | K3: 🟡 未核
A4: 3 | B4: F2 / 4.2 模式关系规则 | C4: VOI-03 | D4: A / C / E 优先级 | E4: A / C / E 优先级：C（云端） > E（微信） > A（现场） | F4: 【真机】按模式进出路径用本地语音 / commx 文本 / 云端 Qt 触发，核对 state/mode、cmd/mode/ack、喇叭与麦克风门控（state/audio）、payload /status 与现场听感。 | K4: 🟡 未核
A5: 4 | B5: F2 / 4.2 模式关系规则 | C5: VOI-04 | D5: A / C / E 为相互独立的会话（独立 session），不共享对话上下文 | E5: A / C / E 为相互独立的会话（独立 session），不共享对话上下文 | F5: 【真机】按模式进出路径用本地语音 / commx 文本 / 云端 Qt 触发，核对 state/mode、cmd/mode/ack、喇叭与麦克风门控（state/audio）、payload /status 与现场听感。 | K5: 🟡 未核
A6: 5 | B6: F2 / 4.2 模式关系规则 | C6: VOI-05 | D6: B 模式下云端语音无法下达控制任务指令（云端麦克风此刻被征用为广播源，音频直通喇叭不进 ASR） | E6: B 模式下云端语音无法下达控制任务指令（云端麦克风此刻被征用为广播源，音频直通喇叭不进 ASR） | F6: 【真机】按模式进出路径用本地语音 / commx 文本 / 云端 Qt 触发，核对 state/mode、cmd/mode/ack、喇叭与麦克风门控（state/audio）、payload /status 与现场听感。 | K6: 🟡 p4 在 B 模式丢弃云端语音（代码 + 单测），真机未单独核
A7: 6 | B7: F2 / 4.4 A 模式 · 现场对话 | C7: VOI-10 | D7: 通过本地 USB 麦克风接收现场人员语音（ 2026-07-31 复原为生效表述 | E7: 通过本地 USB 麦克风接收现场人员语音（ 2026-07-31 复原为生效表述；2026-07-25 的「作废重写」本身是错的，见本节末订正说明）。 实测规格（主会话 2026-07-31 在 ORIN 上探测）：USB PnP Audio Device — JMTek, LLC. 0c76:161f · ALSA card 0, device 0（hw:0,0）· USB 路径 usb-3610000.usb-2.1（full speed）· S16_LE / 单声道 / 48000 Hz（唯一采样率）。 链路：USB MIC（48 k）→ p2_core（audio_io，声卡独占者，见 11 RT-A1）→ 3:1 抽取到 16 k → rt/audio/mic → P4 ASR。 不成立于本期 —— GZH-2 内置 MIC 真实存在且 [40] 已验证，但不接入功能1 的语音闭环，见 VOI-10b | F7: 【真机】按模式进出路径用本地语音 / commx 文本 / 云端 Qt 触发，核对 state/mode、cmd/mode/ack、喇叭与麦克风门控（state/audio）、payload /status 与现场听感。 | K7: ✅ 10-24 真机语音测试；瓶颈：麦克风被 IP67 结构件闷住，识别率受限
A8: 7 | B8: F2 / 4.4 A 模式 · 现场对话 | C8: VOI-10a | D8: 采样率约束与重采样 | E8: 【新 · 2026-07-31】采样率约束与重采样：USB MIC 硬件只支持 48000 Hz，无 16 kHz 直采（请求 16 k 会被 ALSA 拉回 48 k 并告警 rate is not accurate (requested = 16000Hz, got = 48000Hz)）；而 ASR 侧要求 16 kHz · 单声道 · s16le PCM（11 AS-2）⇒ 音频输入链路必须做 48 k → 16 k 重采样。 48000 / 16000 = 3，整数倍 ⇒ 只需干净的 3:1 抽取（decimation）＋ 抗混叠低通，不需要任意比率重采样器。 帧长对齐：20 ms @48 k = 960 样本（落在 PERIOD_SIZE [48, 48000] 内），抽取后 = 320 样本 @16 k， 与 11 §8.7.1 AudioFrame 的 frame_ms=20 / count=320 完全对上。 重采样在采集侧（p2_core audio_io，唯一持有 48 k 原始帧的进程）完成；rt/audio/mic 上发布的恒为 16 k s16le mono，下游不得二次转换。 11 侧已同步（2026-07-31 复核，本待办已回收）： · 11 AS-2 已划掉「全链路零重采样」，改为「采集入口有且只有一次转换」； · 11 AS-10 已补澄清「只管放音侧，不适用于采集侧」； · 11 新增 AF-C1~C5 描述采集侧抽取链路。 该待办已过期，2026-07-31 关闭 —— 冲突已在 11 侧消解，00 侧不再挂待办 | F8: 【真机】按模式进出路径用本地语音 / commx 文本 / 云端 Qt 触发，核对 state/mode、cmd/mode/ack、喇叭与麦克风门控（state/audio）、payload /status 与现场听感。 | K8: ✅ 48k->16k 3:1 抽取在用
A9: 8 | B9: F2 / 4.4 A 模式 · 现场对话 | C9: VOI-10b | D9: GZH-2 内置 MIC 不用于功能1 的 AI 语音闭环 | E9: GZH-2 内置 MIC 不用于功能1 的 AI 语音闭环：[40]/[41]（Opus 16 k / 20 ms / 320 样本）真机验证可用（392/392 干净帧），但用户实测其持续实时性只有 ~0.25，不满足实时语音要求 ⇒ 本期不接入 P4 语音管线。 它的用途是功能2 · 远场对讲（机器人 [40] → office 喇叭，逐字转发，无 ASR/LLM）， 功能2 本期后做 ⇒ [40] 在本期是备用能力。 协议登记保留（它是真实能力） | F9: 【真机】按模式进出路径用本地语音 / commx 文本 / 云端 Qt 触发，核对 state/mode、cmd/mode/ack、喇叭与麦克风门控（state/audio）、payload /status 与现场听感。 | K9: 未核
A10: 9 | B10: F2 / 4.4 A 模式 · 现场对话 | C10: VOI-11 | D10: ASR → LLM → 任务指令解析 → 执行 | E10: ASR → LLM → 任务指令解析 → 执行；同时 TTS 语音应答 | F10: 【真机】按模式进出路径用本地语音 / commx 文本 / 云端 Qt 触发，核对 state/mode、cmd/mode/ack、喇叭与麦克风门控（state/audio）、payload /status 与现场听感。 | K10: ✅ 10-24 真机（缺陷见记录）
A11: 10 | B11: F2 / 4.4 A 模式 · 现场对话 | C11: VOI-11a | D11: TTS 播报与执行下发是并行的两条路，TTS 不在关键路径上（L1a，见 CMD-35） | E11: TTS 播报与执行下发是并行的两条路，TTS 不在关键路径上（L1a，见 CMD-35）。 三段式 ASR→LLM→TTS 中，只有 ASR → 解析 在关键路径上；TTS 与 ROS 2 运动下发同时发出。 例外是 L1b：TTS 播完才执行，此时 TTS 在关键路径上，延迟按 CMD-61 计 | F11: 【真机】按模式进出路径用本地语音 / commx 文本 / 云端 Qt 触发，核对 state/mode、cmd/mode/ack、喇叭与麦克风门控（state/audio）、payload /status 与现场听感。 | K11: 未核
A12: 11 | B12: F2 / 4.4 A 模式 · 现场对话 | C12: VOI-11b | D12: 规范式说法必须走 fastpath 直出，不进 LLM —— 如 沿X号路径巡逻、前进N米 | E12: 规范式说法必须走 fastpath 直出，不进 LLM —— 如 沿X号路径巡逻、前进N米。这是 CMD-60 的 2 秒指标能否达标的唯一决定因素，见 16 §6.6 与 CMD-63 | F12: 【真机】按模式进出路径用本地语音 / commx 文本 / 云端 Qt 触发，核对 state/mode、cmd/mode/ack、喇叭与麦克风门控（state/audio）、payload /status 与现场听感。 | K12: 未核
A13: 12 | B13: F2 / 4.4 A 模式 · 现场对话 | C13: VOI-12 | D13: 优先级最低，可被 C（云端）和 E（微信）抢占 | E13: 优先级最低，可被 C（云端）和 E（微信）抢占 | F13: 【真机】按模式进出路径用本地语音 / commx 文本 / 云端 Qt 触发，核对 state/mode、cmd/mode/ack、喇叭与麦克风门控（state/audio）、payload /status 与现场听感。 | K13: 未核
... A23: 22 | B23: F2 / 4.7 D 模式 · 自主报警 | C23: VOI-40 | D23: 机器人作业中发现可疑情况，自主进入报警模式 | E23: 机器人作业中发现可疑情况，自主进入报警模式 | F23: 【真机】按模式进出路径用本地语音 / commx 文本 / 云端 Qt 触发，核对 state/mode、cmd/mode/ack、喇叭与麦克风门控（state/audio）、payload /status 与现场听感。 | K23: ❌ 感知自主进入未接线（规则引擎依赖感知）
A24: 23 | B24: F2 / 4.7 D 模式 · 自主报警 | C24: VOI-41 | D24: 进入途径两种 | E24: 进入途径两种：① 感知自主触发；② 语音或文本任务指令下发进入 | F24: 【真机】按模式进出路径用本地语音 / commx 文本 / 云端 Qt 触发，核对 state/mode、cmd/mode/ack、喇叭与麦克风门控（state/audio）、payload /status 与现场听感。 | G24: 通过 | H24: ② 指令进入：cmd/mode set_voice_mode alarm，0.1-0.2 s 回 accepted；设备 func1->deter，驱离启动。① 感知自主触发未接线，不在本次范围。 | I24: Claude（AI）+ 现场工程师 | J24: 2026-10-28 | K24: ② 指令进入 ✅（10-28/29）；① 感知自主触发 ❌ 未接线
A25: 24 | B25: F2 / 4.7 D 模式 · 自主报警 | C25: VOI-42 | D25: 触发流程 | E25: 触发流程：先上报事件至 HMI + 发布事件消息，然后自主切换至 D 模式 | F25: 【真机】按模式进出路径用本地语音 / commx 文本 / 云端 Qt 触发，核对 state/mode、cmd/mode/ack、喇叭与麦克风门控（state/audio）、payload /status 与现场听感。 | K25: ❌ 自主触发链路未接线
A26: 25 | B26: F2 / 4.7 D 模式 · 自主报警 | C26: VOI-43 | D26: D 模式行为 | E26: 【2026-07-25 真机订正】D 模式行为：警笛开启（8519 播 WAV）＋ 红蓝警示灯双闪（MSG_REDBLUE 0x07）＋ 探照灯常亮最亮（MSG_LIGHT＋MSG_BRIGHT=30， 不闪）＋ 自主喊话（如"您已进入管制区域，请立即离开！"）。 订正理由：同 VOI-22 —— "警灯爆闪"会被实现成 MSG_STROBE（探照灯爆闪），而那样本该常亮补光的探照灯反而在闪，夜间感知（PER-42）随之失效。权威判据见 PAY-02c | F26: 【真机】按模式进出路径用本地语音 / commx 文本 / 云端 Qt 触发，核对 state/mode、cmd/mode/ack、喇叭与麦克风门控（state/audio）、payload /status 与现场听感。 | G26: 通过 | H26: 四次真机进入 D：警笛 + 红蓝双闪 mode 1 + 探照灯常亮亮度 30，喇叭由 alarm_d 持有、门控 speaker_active、运动 hold；退出灯全灭回 func1。遗留：约 203 s 停喊话时当前句被截断（16:04:12），待下次现场复测。 | I26: Claude（AI）+ 现场工程师 | J26: 2026-10-29 | K26: ✅ 10-28/29 真机：警笛 + 红蓝双闪 + 探照灯常亮；约 203 s 停喊话会截断半句，待下次现场复测
A27: 26 | B27: F2 / 4.7 D 模式 · 自主报警 | C27: VOI-44 | D27: D 模式持续保持，直至下列任一条件满足 | E27: D 模式持续保持，直至下列任一条件满足： ① 可疑人物消失 ② 可疑人物退出电子围栏以外 ③ 云端或微信任一终端下达文本或语音指令退出 | F27: 【真机】按模式进出路径用本地语音 / commx 文本 / 云端 Qt 触发，核对 state/mode、cmd/mode/ack、喇叭与麦克风门控（state/audio）、payload /status 与现场听感。 | G27: 通过 | H27: ③ 指令退出：exit_alarm 回 accepted，设备回 func1、灯灭、开麦、exit_reason=requested。①② 未接线，不在本次范围。 | I27: Claude（AI）+ 现场工程师 | J27: 2026-10-28 | K27: ③ 指令退出 ✅；① 目标消失、② 出围栏 ❌ 未接线
A28: 27 | B28: F2 / 4.7 D 模式 · 自主报警 | C28: VOI-45 | D28: D 模式期间的运动行为按 NAV-50 配置执行 | E28: D 模式期间的运动行为按 NAV-50 配置执行 | F28: 【真机】按模式进出路径用本地语音 / commx 文本 / 云端 Qt 触发，核对 state/mode、cmd/mode/ack、喇叭与麦克风门控（state/audio）、payload /status 与现场听感。 | K28: ✅/🟡 下发 hold 已确认（10-28/29），机器人当时趴着，行走中被压停未验
A29: 28 | B29: F2 / 4.7 D 模式 · 自主报警 | C29: VOI-46 | D29: D 模式期间 PTZ 自动进入跟踪模式，见 PAY-22 | E29: D 模式期间 PTZ 自动进入跟踪模式，见 PAY-22。 订正：此处「跟踪」＝ 开环随动（PAY-22），不含位置校正、不保证与机体 yaw 一致。 云端手动控制随时可抢占（CON-01 域⑤） | F29: 【真机】按模式进出路径用本地语音 / commx 文本 / 云端 Qt 触发，核对 state/mode、cmd/mode/ack、喇叭与麦克风门控（state/audio）、payload /status 与现场听感。 | K29: 🟡 B/D 以 auto_track 持有云台域（10-28 真机）；本期不做真跟踪（机体 hold，set_track 未实现）
A30: 29 | B30: F2 / 4.7 D 模式 · 自主报警 | C30: VOI-47 | D30: 喊话内容应支持预设语句库（可配置多条），而非硬编码单句 | E30: 正式需求（ 原【建议】·§0.4a① 结账 2026-07-31） 喊话内容应支持预设语句库（可配置多条），而非硬编码单句 | F30: 【真机】按模式进出路径用本地语音 / commx 文本 / 云端 Qt 触发，核对 state/mode、cmd/mode/ack、喇叭与麦克风门控（state/audio）、payload /status 与现场听感。 | K30: 🟡 设备只支持单条台词（DT-7），预设语句库未落到 D 模式
A31: 30 | B31: F2 / 4.8 E 模式 · 外部指令通道（企业微信） | C31: VOI-50 | D31: 当前营区环境微信不可用 | E31: 当前营区环境微信不可用。E 模式为预留功能，供其他场景落地时使用 | F31: 【真机】按模式进出路径用本地语音 / commx 文本 / 云端 Qt 触发，核对 state/mode、cmd/mode/ack、喇叭与麦克风门控（state/audio）、payload /status 与现场听感。 | K31: 按需求为预留功能
A32: 31 | B32: F2 / 4.8 E 模式 · 外部指令通道（企业微信） | C32: VOI-51 | D32: 形态为企业微信 bot，支持语音和文本两种指令 | E32: 形态为企业微信 bot，支持语音和文本两种指令 | F32: 【真机】按模式进出路径用本地语音 / commx 文本 / 云端 Qt 触发，核对 state/mode、cmd/mode/ack、喇叭与麦克风门控（state/audio）、payload /status 与现场听感。 | K32: 🟡 p5 有 wecom 通道代码，未接真实企业微信
A33: 32 | B33: F2 / 4.8 E 模式 · 外部指令通道（企业微信） | C33: VOI-52 | D33: 机器狗直连微信服务器，不经由云端后台中转，与云端通道网络路径相互独立 | E33: 机器狗直连微信服务器，不经由云端后台中转，与云端通道网络路径相互独立 | F33: 【真机】按模式进出路径用本地语音 / commx 文本 / 云端 Qt 触发，核对 state/mode、cmd/mode/ack、喇叭与麦克风门控（state/audio）、payload /status 与现场听感。 | K33: 未核
A34: 33 | B34: F2 / 4.8 E 模式 · 外部指令通道（企业微信） | C34: VOI-53 | D34: 架构上应抽象为可插拔的"外部指令通道"，微信仅为其一个实现 | E34: 正式需求（ 原【建议】·§0.4a① 结账 2026-07-31） 架构上应抽象为可插拔的"外部指令通道"，微信仅为其一个实现。以便在合规受限或场景变化时替换为客户 App / 短信网关 / 专用终端，上层代码不变 | F34: 【真机】按模式进出路径用本地语音 / commx 文本 / 云端 Qt 触发，核对 state/mode、cmd/mode/ack、喇叭与麦克风门控（state/audio）、payload /status 与现场听感。 | K34: 🟡 未核
A35: 34 | B35: F2 / 4.8 E 模式 · 外部指令通道（企业微信） | C35: VOI-54 | D35: 待确认 | E35: 待确认：封闭加密营区网络下微信的实际连通路径；以及巡防语音/文本/图片经第三方服务器的合规性判断 | F35: 【真机】按模式进出路径用本地语音 / commx 文本 / 云端 Qt 触发，核对 state/mode、cmd/mode/ack、喇叭与麦克风门控（state/audio）、payload /status 与现场听感。 | K35: 待确认项
A36: 35 | B36: F2 / 4.9 音频资源约束 | C36: VOI-60 | D36: 喊话喇叭为独占资源，A/B/C/D/E 的音频输出全部竞争此资源，须统一仲裁，见 CON-01 | E36: 喊话喇叭为独占资源，A/B/C/D/E 的音频输出全部竞争此资源，须统一仲裁，见 CON-01 | F36: 【真机】按模式进出路径用本地语音 / commx 文本 / 云端 Qt 触发，核对 state/mode、cmd/mode/ack、喇叭与麦克风门控（state/audio）、payload /status 与现场听感。 | G36: 通过 | H36: D 期间发 tts_local，被拒 E_BUSY（speaker held by alarm_d），无插播。 | I36: Claude（AI）+ 现场工程师 | J36: 2026-10-29 | K36: ✅ 10-28/29 真机：喊话 / 报警期间 TTS 被拒（E_BUSY），可被抢占
A37: 36 | B37: F2 / 4.9 音频资源约束 | C37: VOI-61 | D37: 本地麦克风为独占资源，仅 A 模式使用（ 即 hw:0,0 的 USB MIC，由 p2_core audio_io 独… | E37: 本地麦克风为独占资源，仅 A 模式使用（ 即 hw:0,0 的 USB MIC，由 p2_core audio_io 独占持有，见 VOI-10 / 11 RT-A1） | F37: 【真机】按模式进出路径用本地语音 / commx 文本 / 云端 Qt 触发，核对 state/mode、cmd/mode/ack、喇叭与麦克风门控（state/audio）、payload /status 与现场听感。 | K37: ✅ p2 独占 HK-MIC
A38: 37 | B38: F2 / 4.9 音频资源约束 | C38: VOI-62 | D38: 半双工门控（正式需求，2026-07-31 定案， 已去除） | E38: 半双工门控（正式需求，2026-07-31 定案， 已去除）：喇叭出声时必须强制关闭本地 ASR 输入，否则会导致 ASR 自触发、LLM 自问自答。 理由是结构性的、不可绕过：本期 TTS 由 GZH-2 设备内合成并播放（走 [31]/[32]，只发文本，不传音频），回声路径为 TTS 文本 → GZH-2【设备内】合成 → 喇叭 110 dBA@1 m / 15 W → 空气 → ORIN 的 USB MIC ⇒ 上装侧从来没有拿到过播出的音频波形 ⇒ AEC 拿不到参考信号 ⇒ AEC 在结构上不可能做。 这不是「AEC 很难」，是「AEC 没有输入」 —— 因此本条不存在「用更好的算法绕过去」的分支 | F38: 【真机】按模式进出路径用本地语音 / commx 文本 / 云端 Qt 触发，核对 state/mode、cmd/mode/ack、喇叭与麦克风门控（state/audio）、payload /status 与现场听感。 | G38: 通过 | H38: D/B 期间 rt/audio/mic 关闭（muted 计数增长、published 不增），退出后恢复；C1 上线时曾因租约未续致永久静音，已修（d24493c）。 | I38: Claude（AI）+ 现场工程师 | J38: 2026-10-28 | K38: ✅ 10-28/29 真机：B/D 期间关麦、退出开麦；门控 reason 取值与 11 §8.9.2 闭集不一致（已开卡片）
A39: 38 | B39: F2 / 4.9 音频资源约束 | C39: VOI-63 | D39: 门控逻辑必须由音频仲裁器统一管理，不得由各模式各自实现 | E39: 正式需求（2026-07-31 定案， 已去除）：门控逻辑必须由音频仲裁器统一管理，不得由各模式各自实现 | F39: 【真机】按模式进出路径用本地语音 / commx 文本 / 云端 Qt 触发，核对 state/mode、cmd/mode/ack、喇叭与麦克风门控（state/audio）、payload /status 与现场听感。 | K39: ✅ 门控由 p2 统一管理

Sheet F3 载荷控制
A1: 序号 | B1: 测试类 | C1: 需求编号 | D1: 测试功能 | E1: 需求描述（摘自 00） | F1: 测试方法 | G1: 测试结果 | H1: 备注 | I1: 测试人 | J1: 测试时间 | K1: 现状评估（2026-10-29）
A2: 1 | B2: F3 / 5.1 三合一载荷 | C2: PAY-01 | D2: GZH-2 三合一载荷（192.168.144.38）包含四个功能通道 | E2: 【2026-07-25 真机订正】GZH-2 三合一载荷（192.168.144.38）包含四个功能通道： ① 喊话喇叭（110 dBA @1 m / 15 W，端口 8519 ＝ 音频） ② 红蓝警示灯（端口 8529 ＝ 灯光，MSG_REDBLUE ＝ 0x07） ③ 照明灯 ＝ 补光灯/探照灯（8529，MSG_LIGHT ＝ 0x01 ＋ MSG_BRIGHT ＝ 0x02，亮度 0–30） ④ 收音 MIC（[40]/[41]， 本期不接入功能1 语音闭环，见 VOI-10b） 订正理由：原文①把「警笛」与「爆闪灯」并成一件设备 —— 真机上警笛是音频（8519 播 WAV，无独立硬件通道）、灯光是 8529，二者不同端口；②把两种灯混为一谈；③漏掉内置 MIC | F2: 【真机】经语音 D/E 类、cmd/payload、云端 cmd/ptz 触发，核对 payload /status、云台回执，并由现场观察灯光 / 声音 / 云台动作。 | K2: ✅ 喊话 / 红蓝 / 探照灯 / 警笛通道在用（10-28/29）
A3: 2 | B3: F3 / 5.1 三合一载荷 | C3: PAY-01a | D3: 载荷的独占粒度 ＝ 设备级，不是通道级 | E3: 【新增 · 定义 §1.4 载荷行引用的编号】载荷的独占粒度 ＝ 设备级，不是通道级： 对外是一台设备，由 payload-service 进程独占持有（ 14 PAY-L2 ＝ GZH-2 socket 的唯一持有者；进程内串行化所有下发， P2 / P4 均不得直连 8519/8529）； 但 8519（音频）与 8529（灯光）是两个独立 TCP socket，可并发（真机已验证）—— 因此「放警笛」与「点红蓝灯」不互相排队； 8519 内部才是串行的：警笛 WAV 与 TTS 喊话共用同一个喇叭、同一条 8519 链路 ⇒ 警笛与喊话不会同时响，必然串行（14 §7.3 Phase A / Phase B 即此约束的产物）。 仲裁映射：喇叭 ＝ CON-01 域②（8519）；灯光 ＝ CON-01 域④（8529）—— 两域互不阻塞。 作废 —— 照该表述实现会把灯光排在音频后面，D 模式下灯要等警笛播完才亮 | F3: 【真机】经语音 D/E 类、cmd/payload、云端 cmd/ptz 触发，核对 payload /status、云台回执，并由现场观察灯光 / 声音 / 云台动作。 | K3: 未核
A4: 3 | B4: F3 / 5.1 三合一载荷 | C4: PAY-02 | D4: 灯光/警笛状态由模式驱动，语义按 PAY-02c 定义的通道映射执行 | E4: 【2026-07-25 真机订正】灯光/警笛状态由模式驱动，语义按 PAY-02c 定义的通道映射执行： D 模式 → 警笛 ON ＋ 红蓝双闪 ON ＋ 探照灯常亮（不闪） B 模式 → 警笛 OFF ＋ 红蓝双闪 ON ＋ 探照灯按 auto 档判据 订正理由：「爆闪」一词在真机上对应两个不同寄存器，照原文实现会驱错寄存器（威慑双闪打到探照灯上，本该常亮的补光灯反而在闪） | F4: 【真机】经语音 D/E 类、cmd/payload、云端 cmd/ptz 触发，核对 payload /status、云台回执，并由现场观察灯光 / 声音 / 云台动作。 | K4: ✅ B/D 进出灯光由模式驱动（10-28/29）
A5: 4 | B5: F3 / 5.1 三合一载荷 | C5: PAY-02c | D5: 全文档出现的「爆闪 / strobe」一词，一律按 §5.1.1 的通道映射解释 | E5: 【新增 · 灯光语义的唯一权威判据】全文档出现的「爆闪 / strobe」一词，一律按 §5.1.1 的通道映射解释。 完整定义（通道映射 · 模式→输出 · 四条硬约束）见下方 §5.1.1 —— 因内容含表格，独立成节，不塞进本行 | F5: 【真机】经语音 D/E 类、cmd/payload、云端 cmd/ptz 触发，核对 payload /status、云台回执，并由现场观察灯光 / 声音 / 云台动作。 | K5: ✅ 爆闪语义按红蓝双闪落地
A6: 5 | B6: F3 / 5.1 三合一载荷 | C6: PAY-02b | D6: 底盘灯与我方载荷灯必须分开建模 | E6: 底盘灯与我方载荷灯必须分开建模：底盘提供前/后照明灯开关 + 头/尾灯自定义灯语（6 种模式），但灯语颜色仅黑/白/绿/蓝，无红色。因此警示（红蓝双闪）的威慑效果必须由我方三合一载荷提供，底盘灯仅作辅助照明。 实测后本条更硬：红蓝警示灯是载荷独有通道（MSG_REDBLUE），底盘侧物理上没有红色（11 §9.4.1） | F6: 【真机】经语音 D/E 类、cmd/payload、云端 cmd/ptz 触发，核对 payload /status、云台回执，并由现场观察灯光 / 声音 / 云台动作。 | K6: 未核
A7: 6 | B7: F3 / 5.1 三合一载荷 | C7: PAY-03 | D7: 照明灯（＝探照灯/补光灯，MSG_LIGHT＋MSG_BRIGHT）按环境光自动控制（auto 档），并作为夜间感知的组… | E7: 正式需求（原【建议】，2026-07-31 结账）：照明灯（＝探照灯/补光灯，MSG_LIGHT＋MSG_BRIGHT）按环境光自动控制（auto 档），并作为夜间感知的组成部分，见 PER-40 / PER-42。 落点：14 §4.3.2 light_effective 判据链； 由 night_patrol.enabled 整组开关控制（PER-40）。 注意：auto 是档位（操作员意图），模式不改档位，只影响 light_effective —— 否则 D 模式退出后操作员会发现自己的 auto 档不见了 | F7: 【真机】经语音 D/E 类、cmd/payload、云端 cmd/ptz 触发，核对 payload /status、云台回执，并由现场观察灯光 / 声音 / 云台动作。 | K7: ❌ 自动照明未接线（标定值为 null）
A8: 7 | B8: F3 / 5.1 三合一载荷 | C8: PAY-04 | D8: 喊话、红蓝双闪属于对外部有实际影响的动作，误触发有现实后果，必须分级授权 | E8: 正式需求（原【建议】，2026-07-31 结账）：喊话、红蓝双闪属于对外部有实际影响的动作，误触发有现实后果，必须分级授权： L1 自动（照明） L2 策略允许 + 记录（预设语句喊话、警示灯） L3 需人工确认（自定义喊话内容、持续跟随） 落点：18 §0.3 确认级别表 · CMD-33。 本条与 §4.10.3 的 L0/L1a/L1b/L2/L3 是同一套级别，不是两套 | F8: 【真机】经语音 D/E 类、cmd/payload、云端 cmd/ptz 触发，核对 payload /status、云台回执，并由现场观察灯光 / 声音 / 云台动作。 | K8: 🟡 确认级别有单测
A9: 8 | B9: F3 / 5.1 三合一载荷 | C9: PAY-05 | D9: 不得由 LLM 直接触发 L2/L3 动作 | E9: 正式需求（原【建议】，2026-07-31 结账）：不得由 LLM 直接触发 L2/L3 动作。LLM 可"建议"，执行必须经策略层校验和/或人工确认。 落点：16 的确定性校验层 · CMD-40「LLM 不产生数据」 | F9: 【真机】经语音 D/E 类、cmd/payload、云端 cmd/ptz 触发，核对 payload /status、云台回执，并由现场观察灯光 / 声音 / 云台动作。 | K9: 🟡 未核
A10: 9 | B10: F3 / 5.2 PTZ 云台相机（布控球） | C10: PAY-10 | D10: 观察相机用于落地场景观察 | E10: 观察相机用于落地场景观察。 分辨率订正：主码流实测 2560×1440@25fps（约 3.7 MP）—— 不是 4K（3840×2160）。 是否另有 4K 档位待确认（T-PTZ-6）。 涉及 §11.6 带宽账与云端解码窗口尺寸，不可继续按 4K 规划 | F10: 【真机】经语音 D/E 类、cmd/payload、云端 cmd/ptz 触发，核对 payload /status、云台回执，并由现场观察灯光 / 声音 / 云台动作。 | K10: 🟡 未核：云台能力实测记录在文档；控制链路见 F3 其余行
A11: 10 | B11: F3 / 5.2 PTZ 云台相机（布控球） | C11: PAY-11 | D11: 支持 X 轴（pan）0–360° 与 Y 轴（tilt）±90° 控制 | E11: 支持 X 轴（pan）0–360° 与 Y 轴（tilt）±90° 控制。 实测能力集：MaxPTRange pan 0–36000、tilt −9000 – +9000， 单位 0.01°；MaxZoom 3300；方向数 8。支持 Preset / Zoom / Focus / Iris / Wiper / Guard(4 组, 模式 0–3) / PlanPatrol / Rectify；不支持 RecordPatrol · AutoWiper | F11: 【真机】经语音 D/E 类、cmd/payload、云端 cmd/ptz 触发，核对 payload /status、云台回执，并由现场观察灯光 / 声音 / 云台动作。 | K11: 🟡 未核：云台能力实测记录在文档；控制链路见 F3 其余行
A12: 11 | B12: F3 / 5.2 PTZ 云台相机（布控球） | C12: PAY-11b | D12: 待实测（T-PTZ-3） | E12: 待实测（T-PTZ-3）：能力集声明的 tilt ±90° 是协议上限，机械实际可达范围可能更小（11 V-24 曾按典型 −90 ~ +30 假设）。 待实测期间的实现行为（失效方向安全）：tilt 软限位取保守值 −90° ~ +30° 并做成配置项 ptz.tilt_limit_deg（进 CFG-11 安全参数范围断言）； 实测放宽只许外扩，不得在实测前按 ±90 放行 | F12: 【真机】经语音 D/E 类、cmd/payload、云端 cmd/ptz 触发，核对 payload /status、云台回执，并由现场观察灯光 / 声音 / 云台动作。 | K12: 🟡 未核：云台能力实测记录在文档；控制链路见 F3 其余行
A13: 12 | B13: F3 / 5.2 PTZ 云台相机（布控球） | C13: PAY-12 | D13: 云端通过 Zenoh 下发控制指令控制相机 | E13: 云端通过 Zenoh 下发控制指令控制相机 | F13: 【真机】经语音 D/E 类、cmd/payload、云端 cmd/ptz 触发，核对 payload /status、云台回执，并由现场观察灯光 / 声音 / 云台动作。 | K13: 🟡 未核：云台能力实测记录在文档；控制链路见 F3 其余行
... A26: 25 | B26: F3 / 5.2 PTZ 云台相机（布控球） | C26: PAY-29 | D26: 漂移管理 | E26: 漂移管理：开环随动会累积漂移（PAY-22②）。需定义归零触发条件：① 退出 D/B（PAY-27）② 连续随动超过 T_drift ③ 操作员手动。 T_drift 与实际漂移率待实测（T-PTZ-5） —— 因无位置回读，漂移只能用外部量测（视觉标尺 / 人工判读）标定，不能自测。 待实测期间的实现行为（失效方向安全）：ptz.t_drift_s 缺省 60 s（ 明标"无依据的工程初值，须在配置注释里写明"）， 取小值的代价只是"多回一次预置位"，取大值的代价是"越飘越离谱且无人察觉" ⇒ 偏小是安全方向 | F26: 【真机】经语音 D/E 类、cmd/payload、云端 cmd/ptz 触发，核对 payload /status、云台回执，并由现场观察灯光 / 声音 / 云台动作。 | K26: ❌ 未实现
A27: 26 | B27: F3 / 5.3【新】PTZ 实测约束（C28） | C27: PAY-30 | D27: 云台是单一共用资源（U49） | E27: 云台是单一共用资源（U49）：一台布控球 ＝ 一个云台面 ＋ 两个相机（可见光 .66.13、红外 .66.108），两相机物理共面，X/Y 运动效果对等。 三条推论： ① ptz_* 指令不带 camera_id / stream 槽位（18 E 类条数不变）； ② CON-01 域⑤ 仍是单一资源，不按相机拆分； ③ 「看哪一路视频」是视频流选择（媒体面，属 17），不是云台控制，不进指令集 | F27: 【真机】经语音 D/E 类、cmd/payload、云端 cmd/ptz 触发，核对 payload /status、云台回执，并由现场观察灯光 / 声音 / 云台动作。 | G27: 通过 | H27: 云端点动后 30 s 内进 D 照常 accepted，云台域仍归 manual_cloud；30 s 后 auto_track 接手；退出释放。 | I27: Claude（AI）+ 现场工程师 | J27: 2026-10-28 | K27: ✅ 云台域接入仲裁，state/arb/ptz 反映真实持有者（10-28 真机）
A28: 27 | B28: F3 / 5.3【新】PTZ 实测约束（C28） | C28: PAY-31 | D28: 唯一可用的点动原语是 ONVIF ContinuousMove | E28: 唯一可用的点动原语是 ONVIF ContinuousMove：LAPI 的 944 个端点里没有连续点动接口。 认证必须 WS-Security PasswordDigest，且 不能叠加 HTTP 认证（叠加即失败）。 每条 ONVIF 命令 58 ms（持久连接仅降到 55 ms）→ 开销在相机侧，不在网络侧，优化网络无效 → 控制频率上限 17 Hz。 任何设计不得假设高于 17 Hz 的云台控制回路 | F28: 【真机】经语音 D/E 类、cmd/payload、云端 cmd/ptz 触发，核对 payload /status、云台回执，并由现场观察灯光 / 声音 / 云台动作。 | K28: ✅ ContinuousMove 点动（云端 v0.2，10-28 真机）
A29: 28 | B29: F3 / 5.3【新】PTZ 实测约束（C28） | C29: PAY-32 | D29: 绝对定位与位置回读均不可用 | E29: 绝对定位与位置回读均不可用： ① 绝对定位在 PELCO-D 外置云台下是空操作 —— 返回成功但不动（ 最坑的一点：它不报错，上层会误判成功）； ② 位置回读恒为假值 (180, 0)。 因此以下能力在本项目中一律不存在，任何文档不得再引用：绝对角控制 · 位置闭环 · 云台角度量测 · 基于角度的坐标反投影 · 「是否真的归零」的自校验。 上层收到"成功"响应时必须视为"命令已被接受"，不得视为"动作已完成" | F29: 【真机】经语音 D/E 类、cmd/payload、云端 cmd/ptz 触发，核对 payload /status、云台回执，并由现场观察灯光 / 声音 / 云台动作。 | K29: 审查：按约束不用绝对定位
A30: 29 | B30: F3 / 5.3【新】PTZ 实测约束（C28） | C30: PAY-33 | D30: 归零 ＝ Preset（能力集 SupportPreset=1） | E30: 归零 ＝ Preset（能力集 SupportPreset=1）。 不存在其他归零手段。 T-PTZ-1 未闭前，ptz_home 与一切"归位"语义均为"尽力而为"，不得作为其他功能的前置保证 | F30: 【真机】经语音 D/E 类、cmd/payload、云端 cmd/ptz 触发，核对 payload /status、云台回执，并由现场观察灯光 / 声音 / 云台动作。 | K30: ❌ Preset 归零未实现
A31: 30 | B31: F3 / 5.3【新】PTZ 实测约束（C28） | C31: PAY-34 | D31: 双栈冲突一律以 LAPI 为准（LAPI 是设备原生，ONVIF 是适配层） | E31: 双栈冲突一律以 LAPI 为准（LAPI 是设备原生，ONVIF 是适配层）。 分工：点动/停止/Preset 走 ONVIF；对焦模式 · 码率 · I 间隔 · 屏蔽触发 · 能力查询走 LAPI。 2026-08-05 注：本条不改 —— 云台码率控制取消后，「码率 / I 间隔」仍归 LAPI，只是写入时机收敛为开机一次的基线写入（BIT-34 ③④ / PAY-35）， 运行期不再有任何提升与恢复。 本条是规矩而非建议：凡两侧都能改的项，只允许从 LAPI 改，且写后回读确认（LAPI 可读回，这是它优于 ONVIF 的关键） | F31: 【真机】经语音 D/E 类、cmd/payload、云端 cmd/ptz 触发，核对 payload /status、云台回执，并由现场观察灯光 / 声音 / 云台动作。 | K31: 🟡 未核
A32: 31 | B32: F3 / 5.3【新】PTZ 实测约束（C28） | C32: PAY-35 | D32: 原条目整体作废 | E32: 【2026-08-05 整条重写 —— 用户裁决逐字：「系统不需要支持云台码率的相关控制」】 原条目整体作废：原文要求「云台运动期间临时提升编码码率并缩短 I 间隔（6144 → 16384 kbps / I=50 → 25），退出时恢复原值」，触发方归 P2、前置反向握手取 state/link.uplink.boost_allow —— ptz.boost 特性已从设计中删除，上述全部不再实现。 本条现存的唯一内容 ＝ 码率基线（唯一档）：布控球编码码率与 I 间隔只有一个常态值（实测基线 6144 kbps / I=50），由 BIT-34 开机经 LAPI 写入并逐项回读确认（PAY-34）； 运行期不得有任何提升 / 恢复 / 联动 / 握手动作。 为什么保留编号而不删条：PAY-21 · PAY-27 · PAY-37 · BIT-34 ③④ · CAL-02 ② 共五处引用「码率 / I 间隔基线」，删条会让五处悬空。 随本次一并作废的：COM-58（带宽让路）· COM-58a（前置反向握手）· COM-59（进入/退出滞回）· 11 §4.6.2 的 boost_allow 载体 —— 见 §11.6 墓碑行。 实测事实保留备查（它是 PAY-37 的依据，不是需求）：6144 kbps / I=50 下摇摄清晰度仅静止的 31%；16384 kbps / I=25 可到 51% —— 后者这一档已不存在，现场实际值按 31% 计 | F32: 【真机】经语音 D/E 类、cmd/payload、云端 cmd/ptz 触发，核对 payload /status、云台回执，并由现场观察灯光 / 声音 / 云台动作。 | K32: 🟡 未核
A33: 32 | B33: F3 / 5.3【新】PTZ 实测约束（C28） | C33: PAY-36 | D33: 对焦双栈两个坑，必须在会话开始时显式初始化、结束时恢复 | E33: 对焦双栈两个坑，必须在会话开始时显式初始化、结束时恢复： ① ShieldTrigger.MovePTZ 缺省 0 ＝ 不屏蔽 → 云台一动就重对焦，画面反复拉风箱 → 置 MovePTZ=1； ② ONVIF AutoFocusMode=AUTO 不映射回 LAPI 的 FocusMode → 相机实际停在手动对焦 → 转到不同距离的景物必虚 → 用 LAPI 写 FocusMode=2（自动），退出时确认仍为自动。 两项均须写后回读（PAY-34） | F33: 【真机】经语音 D/E 类、cmd/payload、云端 cmd/ptz 触发，核对 payload /status、云台回执，并由现场观察灯光 / 声音 / 云台动作。 | K33: 🟡 p2 启动时做 F1/F2 对焦初始化（U98），未单独核
A34: 33 | B34: F3 / 5.3【新】PTZ 实测约束（C28） | C34: PAY-37 | D34: 摇摄清晰度有物理下限，不得写入验收指标 | E34: 摇摄清晰度有物理下限，不得写入验收指标：在唯一的码率档 6144 kbps / I=50（PAY-35）下，摇摄清晰度仅为静止的 31%。 损失中有相当一部分是 1/100 s 快门在高速下的运动模糊 —— 物理限制，除非降低云台速度或提高快门（画面会更暗）。 2026-08-05 订正：本条原写「即使按 PAY-35 提到 16384/I=25，摇摄清晰度也只有静止的 51%。 剩余 49% 是 1/100 s 快门…」—— 云台码率控制已取消，16384/I=25 这一档不再存在 ⇒ 现场实际值按 31% 计，不是 51%； 本条结论只会更强，不会变弱（原文对 49% 的成因拆分随该档一并失效，故改为不给固定百分比） 需求方须知："边转边看清"在本硬件上做不到； 现场操作规程应引导"转到位再看"，而不是期待"转的过程中也清晰" | F34: 【真机】经语音 D/E 类、cmd/payload、云端 cmd/ptz 触发，核对 payload /status、云台回执，并由现场观察灯光 / 声音 / 云台动作。 | K34: 🟡 未核
A35: 34 | B35: F3 / 5.3【新】PTZ 实测约束（C28） | C35: PAY-38 | D35: 速度分档 | E35: 速度分档：因 PAY-37，高速摇摄的画面价值很低。 云台点动必须提供粗调/细调两档速度，粗调用于换视场、细调用于对准。 具体速度值待现场手感确认。 待确认期间的实现行为：两档速度做成配置项 ptz.speed_coarse / ptz.speed_fine（ONVIF ContinuousMove 的归一化速度，缺省 0.6 / 0.15， 明标"无依据的工程初值"）； 档位结构本身不是可选项，只有取值待整定 | F35: 【真机】经语音 D/E 类、cmd/payload、云端 cmd/ptz 触发，核对 payload /status、云台回执，并由现场观察灯光 / 声音 / 云台动作。 | K35: ✅ 云端 v0.2 速度档
A36: 35 | B36: F3 / 5.3【新】PTZ 实测约束（C28） | C36: PAY-39 | D36: 失败语义 | E36: 失败语义：因 PAY-32①，"命令成功"不等于"动作发生"。 云台类指令的回执只承诺"已投递并被相机接受"；HMI/语音回复用语须与之一致（ 说"已下发"，不说"已就位"） | F36: 【真机】经语音 D/E 类、cmd/payload、云端 cmd/ptz 触发，核对 payload /status、云台回执，并由现场观察灯光 / 声音 / 云台动作。 | K36: ✅ 回执只承诺已投递（v0.2）
A37: 36 | B37: F3 / 5.4【新】PTZ 直控手感（键盘 / 手柄直控） | C37: PAY-40 | D37: 按住方向键连续转动需用自适应保持时间（实测 C28.5） | E37: 按住方向键连续转动需用自适应保持时间（实测 C28.5）：HOLD_FIRST 0.85 s · HOLD_REPEAT 0.18 s · REPEAT_ARMED 2（收到 2 次重复即判定"真被按住"） | F37: 【真机】经语音 D/E 类、cmd/payload、云端 cmd/ptz 触发，核对 payload /status、云台回执，并由现场观察灯光 / 声音 / 云台动作。 | K37: ✅ jog 续租 / dead-man（v0.2 真机）
A38: 37 | B38: F3 / 5.4【新】PTZ 直控手感（键盘 / 手柄直控） | C38: PAY-41 | D38: HOLD_FIRST 必须 > 终端键盘自动重复的首延迟（约 500 ms），否则出现「转-停-转」顿挫 | E38: HOLD_FIRST 必须 > 终端键盘自动重复的首延迟（约 500 ms），否则出现「转-停-转」顿挫。 v1 用固定 0.30 s（短于首延迟）必然顿挫 —— 这是 v1→v2 的核心修正。 该参数不是可随意调小的调优项，是硬下界 | F38: 【真机】经语音 D/E 类、cmd/payload、云端 cmd/ptz 触发，核对 payload /status、云台回执，并由现场观察灯光 / 声音 / 云台动作。 | K38: ✅ 同上
A39: 38 | B39: F3 / 5.4【新】PTZ 直控手感（键盘 / 手柄直控） | C39: PAY-42 | D39: 松手须能快停 → 进入重复态后把保持时间缩到 HOLD_REPEAT | E39: 松手须能快停 → 进入重复态后把保持时间缩到 HOLD_REPEAT。 停止用 ONVIF Stop，并计入 17 Hz 预算（PAY-31） | F39: 【真机】经语音 D/E 类、cmd/payload、云端 cmd/ptz 触发，核对 payload /status、云台回执，并由现场观察灯光 / 声音 / 云台动作。 | K39: ✅ 云端键盘直控契约 v0.2 真机打通（10-28）

Sheet F4 环境感知
A1: 序号 | B1: 测试类 | C1: 需求编号 | D1: 测试功能 | E1: 需求描述（摘自 00） | F1: 测试方法 | G1: 测试结果 | H1: 备注 | I1: 测试人 | J1: 测试时间 | K1: 现状评估（2026-10-29）
A2: 1 | B2: F4 / 6.1 现有能力（V5 已实现） | C2: PER-01 | D2: 感知系统融合相机与激光雷达数据，运行 YOLOv11n 推理，由 C++ ROS 2 节点实现 | E2: 感知系统融合相机与激光雷达数据，运行 YOLOv11n 推理，由 C++ ROS 2 节点实现 | F2: 【感知团队自测 + 联调】感知侧提交自测报告；联调核对 p1 感知输入计数与拒收、目标世界坐标；可疑判定需接线后真机验证。 | K2: 未核：感知团队负责，在单独测试
A3: 2 | B3: F4 / 6.1 现有能力（V5 已实现） | C3: PER-02 | D3: 每帧发布所有目标物，字段包含 | E3: 每帧发布所有目标物，字段包含： 目标物名称（class） · bbox / mask（多边形） · 置信度 · 运动速度 · track_id · 深度/距离 | F3: 【感知团队自测 + 联调】感知侧提交自测报告；联调核对 p1 感知输入计数与拒收、目标世界坐标；可疑判定需接线后真机验证。 | K3: 未核：感知团队负责，在单独测试
A4: 3 | B4: F4 / 6.1 现有能力（V5 已实现） | C4: PER-03 | D4: 多目标跟踪（MOT）已实现，track_id 可用 —— 这是 D 模式退出判定的基础 | E4: 多目标跟踪（MOT）已实现，track_id 可用 —— 这是 D 模式退出判定的基础 | F4: 【感知团队自测 + 联调】感知侧提交自测报告；联调核对 p1 感知输入计数与拒收、目标世界坐标；可疑判定需接线后真机验证。 | K4: 未核：感知团队负责，在单独测试
A5: 4 | B5: F4 / 6.1 现有能力（V5 已实现） | C5: PER-04 | D5: 当前帧率 27–30 fps | E5: 当前帧率 27–30 fps | F5: 【感知团队自测 + 联调】感知侧提交自测报告；联调核对 p1 感知输入计数与拒收、目标世界坐标；可疑判定需接线后真机验证。 | K5: 未核：感知团队负责，在单独测试
A6: 5 | B6: F4 / 6.1 现有能力（V5 已实现） | C6: PER-05 | D6: 数据由 RNS 订阅 | E6: 数据由 RNS 订阅；云端计算机也订阅，在解码播放视频的同时叠加可视化 | F6: 【感知团队自测 + 联调】感知侧提交自测报告；联调核对 p1 感知输入计数与拒收、目标世界坐标；可疑判定需接线后真机验证。 | K6: 未核：感知团队负责，在单独测试
A7: 6 | B7: F4 / 6.1 现有能力（V5 已实现） | C7: PER-06 | D7: Gemini 336L 提供 metric 深度（带真实尺度） | E7: Gemini 336L 提供 metric 深度（带真实尺度） | F7: 【感知团队自测 + 联调】感知侧提交自测报告；联调核对 p1 感知输入计数与拒收、目标世界坐标；可疑判定需接线后真机验证。 | K7: 未核：感知团队负责，在单独测试
A8: 7 | B8: F4 / 6.2 需补充的能力 | C8: PER-10 | D8: 仍缺 world_pos（WGS84/UTM 世界坐标），它是三项需求的共同前提 | E8: 仍缺 world_pos（WGS84/UTM 世界坐标），它是三项需求的共同前提： ① D 模式退出判定"目标退出电子围栏"（VOI-44） ② 目标导向跟随的距离/方位解算（NAV-50b） ③ 云端地图上标注目标位置 | F8: 【感知团队自测 + 联调】感知侧提交自测报告；联调核对 p1 感知输入计数与拒收、目标世界坐标；可疑判定需接线后真机验证。 | K8: 未核：感知团队负责
A9: 8 | B9: F4 / 6.2 需补充的能力 | C9: PER-11 | D9: world_pos 应在 perception（C++）中计算 | E9: 正式需求（ 原【建议】·§0.4a① 结账 2026-07-31） world_pos 应在 perception（C++）中计算：该节点已有 detection + depth，只需再订阅 RTK 位姿即可换算。一次计算、两个消费者（P1 跟随、P2 围栏判定）共用，避免两侧算出不一致结果 | F9: 【感知团队自测 + 联调】感知侧提交自测报告；联调核对 p1 感知输入计数与拒收、目标世界坐标；可疑判定需接线后真机验证。 | K9: 未核：感知团队负责
A10: 9 | B10: F4 / 6.2 需补充的能力 | C10: PER-12 | D10: "目标消失"判定需设确认窗口，单帧漏检（遮挡、转身）不得判为消失，否则 D 模式会剧烈抖动进出 | E10: 正式需求（ 原【建议】·§0.4a① 结账 2026-07-31） "目标消失"判定需设确认窗口，单帧漏检（遮挡、转身）不得判为消失，否则 D 模式会剧烈抖动进出 | F10: 【感知团队自测 + 联调】感知侧提交自测报告；联调核对 p1 感知输入计数与拒收、目标世界坐标；可疑判定需接线后真机验证。 | K10: 未核：感知团队负责
A11: 10 | B11: F4 / 6.2 需补充的能力 | C11: PER-13 | D11: 待确认 | E11: 待确认：帧率与延迟是两回事。27–30 fps 不等于低延迟，流水线可能 30 fps 运行却有 100 ms 延迟。 按 U54 后的 2.0 m/s 重算：100 ms = 0.20 m（ 作废）。 不要因为数字变小就降低本项优先级 —— 感知延迟直接进 §3.8.2 的 t_延迟（现取 0.4 s，其中我方检测占 200 ms），而 d(2.0) = 1.60 m 已经刹不住 1 m 安全距离；感知延迟每多 100 ms，停车距离就多 0.20 m。需实测从曝光到 RNS 拿到数据的时间，见 §21 测试 T7/T8 | F11: 【感知团队自测 + 联调】感知侧提交自测报告；联调核对 p1 感知输入计数与拒收、目标世界坐标；可疑判定需接线后真机验证。 | K11: 未核：感知团队负责
A12: 11 | B12: F4 / 6.2 需补充的能力 | C12: PER-14 | D12: 待确认 | E12: 待确认：27–30 fps 是 LLM 空闲时还是 LLM 满载时的数字？见测试 T2 | F12: 【感知团队自测 + 联调】感知侧提交自测报告；联调核对 p1 感知输入计数与拒收、目标世界坐标；可疑判定需接线后真机验证。 | K12: 未核：感知团队负责
A13: 12 | B13: F4 / 6.3 【新】自由空间与三传感器分工 | C13: PER-20 | D13: 底盘自带前后 LiDAR，可订阅 | E13: 底盘自带前后 LiDAR，可订阅 | F13: 【感知团队自测 + 联调】感知侧提交自测报告；联调核对 p1 感知输入计数与拒收、目标世界坐标；可疑判定需接线后真机验证。 | K13: ✅/🟡 感知 -> p1 实时数据通路在流动（p1 感知输入计数无拒收）；自由空间语义未核
... A32: 31 | B32: F4 / 6.7【新】观察相机（布控球）与感知管线的边界 | C32: PER-54 | D32: 「云台在动」是"有人正在主动观察"的强信号，应作为一等状态量发布（供 P2 抑制自动行为抢占、供事件系统标注"此段有人在… | E32: 「云台在动」是"有人正在主动观察"的强信号，应作为一等状态量发布（供 P2 抑制自动行为抢占、供事件系统标注"此段有人在看"）。 这个信号免费可得（域⑤ 持有者天然知道）， 不写下来就会被各自重复推断。 2026-08-05 订正：括号内原列有「供 P5 带宽让路 COM-58」这一项，随云台码率控制取消删除。 本条「应作为一等状态量发布」的主张必须保留 —— 它是 state/mode.ptz.moving（14 §4.4.3 BR-0a）存在的需求源，而 ptz.moving 又是 11 §7.16 G32 的数据源； 这条链上任何一环删错，G32 当场悬空 | F32: 【感知团队自测 + 联调】感知侧提交自测报告；联调核对 p1 感知输入计数与拒收、目标世界坐标；可疑判定需接线后真机验证。 | K32: 审查：观察相机不进感知管线

Sheet F5 任务系统
A1: 序号 | B1: 测试类 | C1: 需求编号 | D1: 测试功能 | E1: 需求描述（摘自 00） | F1: 测试方法 | G1: 测试结果 | H1: 备注 | I1: 测试人 | J1: 测试时间 | K1: 现状评估（2026-10-29）
A2: 1 | B2: F5 / 7.1 任务来源 | C2: TSK-01 | D2: 云端通过 Zenoh 下发 JSON 格式文本任务指令，机器人解析并执行 | E2: 云端通过 Zenoh 下发 JSON 格式文本任务指令，机器人解析并执行 | F2: 【云端联调 + 真机】Qt 下发任务，核对受理回执、state/task 状态流转、进度上报与机器人实际执行。 | K2: ✅ 09-04 与甲方 Qt v2.0 首轮联调，T01-T06 都下发过；⚠ 任务执行器未接线，受理后机器人不动
A3: 2 | B3: F5 / 7.1 任务来源 | C3: TSK-02 | D3: 语音指令（A / C / E 模式）经 AI 层翻译后同样产生任务 | E3: 语音指令（A / C / E 模式）经 AI 层翻译后同样产生任务 | F3: 【云端联调 + 真机】Qt 下发任务，核对受理回执、state/task 状态流转、进度上报与机器人实际执行。 | K3: 🟡 未核
A4: 3 | B4: F5 / 7.1 任务来源 | C4: TSK-03 | D4: HMI 点击导航产生任务（见 HMI-10） | E4: HMI 点击导航产生任务（见 HMI-10） | F4: 【云端联调 + 真机】Qt 下发任务，核对受理回执、state/task 状态流转、进度上报与机器人实际执行。 | K4: 未核（HMI 点击导航）
A5: 4 | B5: F5 / 7.1 任务来源 | C5: TSK-04 | D5: 系统自主行为（D 模式触发）产生内部任务 | E5: 系统自主行为（D 模式触发）产生内部任务 | F5: 【云端联调 + 真机】Qt 下发任务，核对受理回执、state/task 状态流转、进度上报与机器人实际执行。 | K5: 按 D-B1 裁定不实现（由 state/mode + 任务让行 mode_takeover 替代）
A6: 5 | B6: F5 / 7.1 任务来源 | C6: TSK-05 | D6: 多任务源必须统一仲裁，见 CON-01 | E6: 多任务源必须统一仲裁，见 CON-01。建议优先级：急停 > 围栏/避障 > 云端 > 微信 > 现场 > 自主 | F6: 【云端联调 + 真机】Qt 下发任务，核对受理回执、state/task 状态流转、进度上报与机器人实际执行。 | K6: 🟡 单测
A7: 6 | B7: F5 / 7.2 任务生命周期 | C7: TSK-10 | D7: V5 已实现任务处理执行调度单元，支持 SQLite3 持久化 | E7: V5 已实现任务处理执行调度单元，支持 SQLite3 持久化 | F7: 【云端联调 + 真机】Qt 下发任务，核对受理回执、state/task 状态流转、进度上报与机器人实际执行。 | K7: 🟡 单测（SQLite / aiosqlite 持久化）
A8: 7 | B8: F5 / 7.2 任务生命周期 | C8: TSK-11 | D8: 任务应为有生命周期的状态机，须包含以下机制 | E8: 正式需求（ 原【建议】·§0.4a① 结账 2026-07-31） 任务应为有生命周期的状态机，须包含以下机制： | F8: 【云端联调 + 真机】Qt 下发任务，核对受理回执、state/task 状态流转、进度上报与机器人实际执行。 | K8: 🟡 状态机单测；❌ 执行器未接线（goto / patrol / return_home / charge / follow / standby / teach）
A9: 8 | B9: F5 / 7.2 任务生命周期 | C9: TSK-12 | D9: task_id + 幂等处理 —— 防止网络重传导致同一任务执行两次 | E9: 正式需求（ 原【建议】·§0.4a① 结账 2026-07-31） task_id + 幂等处理 —— 防止网络重传导致同一任务执行两次 | F9: 【云端联调 + 真机】Qt 下发任务，核对受理回执、state/task 状态流转、进度上报与机器人实际执行。 | K9: 🟡 单测
A10: 9 | B10: F5 / 7.2 任务生命周期 | C10: TSK-13 | D10: 接受/拒绝应答 —— 云端须能确知任务是否被接收，而非盲等 | E10: 正式需求（ 原【建议】·§0.4a① 结账 2026-07-31） 接受/拒绝应答 —— 云端须能确知任务是否被接收，而非盲等 | F10: 【云端联调 + 真机】Qt 下发任务，核对受理回执、state/task 状态流转、进度上报与机器人实际执行。 | K10: ✅ 受理 / 拒绝应答（09-04 联调）
A11: 10 | B11: F5 / 7.2 任务生命周期 | C11: TSK-14 | D11: 前置校验 —— 路径点是否在围栏内、电量是否充足、本体能力是否支持 | E11: 正式需求（ 原【建议】·§0.4a① 结账 2026-07-31） 前置校验 —— 路径点是否在围栏内、电量是否充足、本体能力是否支持。不通过则拒绝并给出原因 | F11: 【云端联调 + 真机】Qt 下发任务，核对受理回执、state/task 状态流转、进度上报与机器人实际执行。 | K11: 🟡 单测
A12: 11 | B12: F5 / 7.2 任务生命周期 | C12: TSK-15 | D12: 进度上报 —— 云端可见执行进度 | E12: 正式需求（ 原【建议】·§0.4a① 结账 2026-07-31） 进度上报 —— 云端可见执行进度 | F12: 【云端联调 + 真机】Qt 下发任务，核对受理回执、state/task 状态流转、进度上报与机器人实际执行。 | K12: 🟡 未核（执行器未接线，无真实进度）
A13: 12 | B13: F5 / 7.2 任务生命周期 | C13: TSK-16 | D13: 取消 / 抢占语义 —— 执行中任务被新任务打断时的行为必须明确定义 | E13: 正式需求（ 原【建议】·§0.4a① 结账 2026-07-31） 取消 / 抢占语义 —— 执行中任务被新任务打断时的行为必须明确定义 | F13: 【云端联调 + 真机】Qt 下发任务，核对受理回执、state/task 状态流转、进度上报与机器人实际执行。 | K13: 🟡 单测
... A19: 18 | B19: F5 / 7.4 续航与充电 | C19: TSK-30 | D19: 低电返航、自动充电、任务被电量中断后的恢复策略已在 §8 充电与续航（CHG）中定义 | E19: 低电返航、自动充电、任务被电量中断后的恢复策略已在 §8 充电与续航（CHG）中定义。 2026-07-31 订正： 已裁定 —— suspended ＋ 断点续跑（§8.4 裁定框； 依 U07a 推定，待甲方书面确认）。 任务状态机与 SQLite schema 按 CHG-32/33/34 实现，不再阻塞编码 | F19: 【云端联调 + 真机】Qt 下发任务，核对受理回执、state/task 状态流转、进度上报与机器人实际执行。 | K19: 见 F11

Sheet F6 事件系统
A1: 序号 | B1: 测试类 | C1: 需求编号 | D1: 测试功能 | E1: 需求描述（摘自 00） | F1: 测试方法 | G1: 测试结果 | H1: 备注 | I1: 测试人 | J1: 测试时间 | K1: 现状评估（2026-10-29）
A2: 1 | B2: F6 / 10. 事件系统需求（EVT） | C2: EVT-01 | D2: 系统运行与作业过程中产生的各类事件，全部通过 Zenoh 发布，由云端计算机订阅 | E2: 系统运行与作业过程中产生的各类事件，全部通过 Zenoh 发布，由云端计算机订阅 | F2: 【联调】触发事件源，核对 event/** -> record.db -> 云端 Qt 显示，含分级、去重、断网补发。 | K2: ✅ 联调在用
A3: 2 | B3: F6 / 10. 事件系统需求（EVT） | C3: EVT-02 | D3: 事件同时供本地 HMI 显示 | E3: 事件同时供本地 HMI 显示 | F3: 【联调】触发事件源，核对 event/** -> record.db -> 云端 Qt 显示，含分级、去重、断网补发。 | K3: 🟡 HMI 显示未核
A4: 3 | B4: F6 / 10. 事件系统需求（EVT） | C4: EVT-10 | D4: 事件是一等公民业务数据流，不是日志 | E4: 正式需求（ 原【建议】·§0.4a① 结账 2026-07-31） 事件是一等公民业务数据流，不是日志。须定义统一 schema | F4: 【联调】触发事件源，核对 event/** -> record.db -> 云端 Qt 显示，含分级、去重、断网补发。 | K4: ✅
A5: 4 | B5: F6 / 10. 事件系统需求（EVT） | C5: EVT-11 | D5: schema 至少包含 | E5: 正式需求（ 原【建议】·§0.4a① 结账 2026-07-31） schema 至少包含：event_id、robot_id、timestamp、source、severity、category、position、related_task_id、media_ref、payload | F5: 【联调】触发事件源，核对 event/** -> record.db -> 云端 Qt 显示，含分级、去重、断网补发。 | K5: ✅
A6: 5 | B6: F6 / 10. 事件系统需求（EVT） | C6: EVT-12 | D6: 事件分级 | E6: 正式需求（ 原【建议】·§0.4a① 结账 2026-07-31） 事件分级：INFO / WARN / ALARM / FAULT | F6: 【联调】触发事件源，核对 event/** -> record.db -> 云端 Qt 显示，含分级、去重、断网补发。 | K6: ✅
A7: 6 | B7: F6 / 10. 事件系统需求（EVT） | C7: EVT-13 | D7: 本地持久化 + 断网补发 | E7: 正式需求（ 原【建议】·§0.4a① 结账 2026-07-31） 本地持久化 + 断网补发。Zenoh pub/sub 不保证送达，断网期间的报警事件丢失在巡防场景中不可接受 | F7: 【联调】触发事件源，核对 event/** -> record.db -> 云端 Qt 显示，含分级、去重、断网补发。 | K7: ✅ record.db 持久化（补发未单独测）
A8: 7 | B8: F6 / 10. 事件系统需求（EVT） | C8: EVT-14 | D8: 去重与抑制窗口 | E8: 正式需求（ 原【建议】·§0.4a① 结账 2026-07-31） 去重与抑制窗口。同一目标持续检测会产生事件洪水 | F8: 【联调】触发事件源，核对 event/** -> record.db -> 云端 Qt 显示，含分级、去重、断网补发。 | K8: 🟡 单测
A9: 8 | B9: F6 / 10. 事件系统需求（EVT） | C9: EVT-15 | D9: 与媒体关联 | E9: 正式需求（ 原【建议】·§0.4a① 结账 2026-07-31） 与媒体关联。报警事件须能关联抓拍图/录像片段（事件走 Zenoh，媒体走 FTP，事件中携带引用） | F9: 【联调】触发事件源，核对 event/** -> record.db -> 云端 Qt 显示，含分级、去重、断网补发。 | K9: 未核
A10: 9 | B10: F6 / 10. 事件系统需求（EVT） | C10: EVT-16 | D10: 仲裁器的每次授予/抢占/释放都应产生审计事件 | E10: 正式需求（ 原【建议】·§0.4a① 结账 2026-07-31） 仲裁器的每次授予/抢占/释放都应产生审计事件。巡防系统必须能回答"当时为什么没喊话/为什么突然停车" | F10: 【联调】触发事件源，核对 event/** -> record.db -> 云端 Qt 显示，含分级、去重、断网补发。 | G10: 通过 | H10: 修复缺 eid（0995634 / 716cc07）后，record.db 查到 arb-p2-* 事件。 | I10: Claude（AI）+ 现场工程师 | J10: 2026-10-28 | K10: ✅ 10-28 修复缺 eid 后，record.db 已存下仲裁事件
A11: 10 | B11: F6 / 10. 事件系统需求（EVT） | C11: EVT-17 | D11: 速度门的每次降速决策应产生事件（降速原因 | E11: 正式需求（ 原【建议】·§0.4a① 结账 2026-07-31） 速度门的每次降速决策应产生事件（降速原因：自由空间不足 / 传感器降级 / RTK 降级），用于事后分析与调参 | F11: 【联调】触发事件源，核对 event/** -> record.db -> 云端 Qt 显示，含分级、去重、断网补发。 | K11: 未核

Sheet F7 通信
A1: 序号 | B1: 测试类 | C1: 需求编号 | D1: 测试功能 | E1: 需求描述（摘自 00） | F1: 测试方法 | G1: 测试结果 | H1: 备注 | I1: 测试人 | J1: 测试时间 | K1: 现状评估（2026-10-29）
A2: 1 | B2: F7 / 11.1 数据平面划分 | C2: COM-01 | D2: 各平面必须能独立降级 | E2: 正式需求（ 原【建议】·§0.4a① 结账 2026-07-31） 各平面必须能独立降级。媒体面或数据面带宽饱和不得影响控制面的急停指令送达，更不得影响本地实时面 | F2: 【联调 / 抓包】核对 Zenoh 通用面与实时面、云端桥、媒体 NAT、FTP 与带宽，必要时抓包。 | K2: ✅ 通用面 / 实时面两个 router 在运行
A3: 2 | B3: F7 / 11.2 【新】本地实时面：RNS ↔ perception 直连方案 | C3: COM-10 | D3: 采用方案 D | E3: 正式需求（ 原【建议】·§0.4a① 结账 2026-07-31） 采用方案 D： ① perception（C++）内嵌 zenoh-cpp 客户端，将感知元数据直接发布到本地专用 Zenoh session（mode: peer，scouting 限定 localhost，不 connect 云端 router） ② 同时保留原有 ROS 2 topic 发布，供 rosbag2 录制、HMI 观测、云端上报 ③ RNS 保持纯 Python，订阅该本地 session ④ 速度指令、RTK、Nav2 cmd_vel 走同一 RT Session | F3: 【联调 / 抓包】核对 Zenoh 通用面与实时面、云端桥、媒体 NAT、FTP 与带宽，必要时抓包。 | K3: ✅ 感知 -> RNS 直连数据在流动
A4: 3 | B4: F7 / 11.2 【新】本地实时面：RNS ↔ perception 直连方案 | C4: COM-11 | D4: 方案 D 收益 | E4: 方案 D 收益：实时路径上完全无 bridge（云端 bridge 崩溃不影响导航）；云端流量突发物理上无法挤占实时路径；RNS 保持纯 Python；仍可用 rosbag2 录 perception 的 ROS 2 topic 做事后复盘；perception 侧改动约 30 行 C++ | F4: 【联调 / 抓包】核对 Zenoh 通用面与实时面、云端桥、媒体 NAT、FTP 与带宽，必要时抓包。 | K4: ✅ 感知 -> RNS 直连数据在流动
A5: 4 | B5: F7 / 11.2 【新】本地实时面：RNS ↔ perception 直连方案 | C5: COM-12 | D5: 方案 D 代价 | E5: 方案 D 代价：perception 双发，两条路径理论上可能因 bug 不一致 —— 用同一份序列化载荷发两次可规避 | F5: 【联调 / 抓包】核对 Zenoh 通用面与实时面、云端桥、媒体 NAT、FTP 与带宽，必要时抓包。 | K5: ✅ 感知 -> RNS 直连数据在流动
A6: 5 | B6: F7 / 11.2 【新】本地实时面：RNS ↔ perception 直连方案 | C6: COM-13 | D6: 方案 B（rclpy）的独有价值在于免费获得 ros2 topic echo、ros2 bag record、TF、rq… | E6: 正式需求（ 原【建议】·§0.4a① 结账 2026-07-31） 方案 B（rclpy）的独有价值在于免费获得 ros2 topic echo、ros2 bag record、TF、rqt 全套工具链。对一个需要在现场排查"当时为什么撞了/为什么没停"的安全关键导航栈，该调试能力价值可观。rclpy 在 20 Hz 小消息下开销可忽略（GIL 问题主要出现在高频大消息场景）。建议先按 D 实施，同时按 NAV-39 抽象接入层，保留后续切换空间 | F6: 【联调 / 抓包】核对 Zenoh 通用面与实时面、云端桥、媒体 NAT、FTP 与带宽，必要时抓包。 | K6: ✅ 感知 -> RNS 直连数据在流动
A7: 6 | B7: F7 / 11.3 控制面（Zenoh） | C7: COM-20 | D7: 系统状态、系统故障由 ROS 2 节点发布，经 Zenoh 桥订阅后再发布 | E7: 系统状态、系统故障由 ROS 2 节点发布，经 Zenoh 桥订阅后再发布 | F7: 【联调 / 抓包】核对 Zenoh 通用面与实时面、云端桥、媒体 NAT、FTP 与带宽，必要时抓包。 | K7: ✅ 控制面与云端桥联调在用
A8: 7 | B8: F7 / 11.3 控制面（Zenoh） | C8: COM-21 | D8: 此设计使本地非 ROS 2 的 Python 进程与云端计算机均可方便订阅同一数据源 | E8: 此设计使本地非 ROS 2 的 Python 进程与云端计算机均可方便订阅同一数据源 | F8: 【联调 / 抓包】核对 Zenoh 通用面与实时面、云端桥、媒体 NAT、FTP 与带宽，必要时抓包。 | K8: ✅ 控制面与云端桥联调在用
A9: 8 | B9: F7 / 11.3 控制面（Zenoh） | C9: COM-22 | D9: Zenoh 不仅是云端桥接，也是 XBRAIN Runtime 各进程间的集成总线 | E9: Zenoh 不仅是云端桥接，也是 XBRAIN Runtime 各进程间的集成总线 | F9: 【联调 / 抓包】核对 Zenoh 通用面与实时面、云端桥、媒体 NAT、FTP 与带宽，必要时抓包。 | K9: ✅ 控制面与云端桥联调在用
A10: 9 | B10: F7 / 11.3 控制面（Zenoh） | C10: COM-23 | D10: AI Runtime、XBRAIN Runtime 与底层 ROS 2 节点（perception / nav2 / q… | E10: AI Runtime、XBRAIN Runtime 与底层 ROS 2 节点（perception / nav2 / quadruped）之间均通过 Zenoh 桥接完成 | F10: 【联调 / 抓包】核对 Zenoh 通用面与实时面、云端桥、媒体 NAT、FTP 与带宽，必要时抓包。 | K10: ✅ 控制面与云端桥联调在用
A11: 10 | B11: F7 / 11.3 控制面（Zenoh） | C11: COM-24 | D11: 云端通过 Zenoh 下发 JSON 任务指令、模式切换指令、PTZ 控制指令 | E11: 云端通过 Zenoh 下发 JSON 任务指令、模式切换指令、PTZ 控制指令 | F11: 【联调 / 抓包】核对 Zenoh 通用面与实时面、云端桥、媒体 NAT、FTP 与带宽，必要时抓包。 | K11: ✅ 控制面与云端桥联调在用
A12: 11 | B12: F7 / 11.3 控制面（Zenoh） | C12: COM-25 | D12: 红线 | E12: 正式需求（ 原【建议】·§0.4a① 结账 2026-07-31） 红线：Zenoh 桥是单点故障。需健康监控 + 自动重启 + 桥失联时的默认行为（建议：继续执行当前任务，禁止接受新任务，禁止 D 模式自主喊话，N 秒后停车等待） | F12: 【联调 / 抓包】核对 Zenoh 通用面与实时面、云端桥、媒体 NAT、FTP 与带宽，必要时抓包。 | K12: ✅ 控制面与云端桥联调在用
A13: 12 | B13: F7 / 11.4 媒体面 | C13: COM-30 | D13: 布控球视频流经 NAT 桥接至通讯网口，云端 RTSP 拉流解码播放（PAY-20 / PAY-20b） | E13: 布控球视频流经 NAT 桥接至通讯网口，云端 RTSP 拉流解码播放（PAY-20 / PAY-20b）。 订正： → 两路 2560×1440@25fps（可见光 ＋ 红外，各约 6.0 Mbps，PAY-10 / §11.6） | F13: 【联调 / 抓包】核对 Zenoh 通用面与实时面、云端桥、媒体 NAT、FTP 与带宽，必要时抓包。 | K13: 🟡 视频走云台 NAT 直通；p5 媒体探测由另一会话开发
... A29: 28 | B29: F7 / 11.6 带宽预算与 QoS | C29: COM-57 | D29: 需估算日均作业数据量 | E29: 正式需求（ 原【建议】·§0.4a① 结账 2026-07-31） 需估算日均作业数据量。6 MB/s 满速下传 1 GB 约 3 分钟；若日产 10 GB 则需半小时满速上行，此数值决定传输调度策略 | F29: 【联调 / 抓包】核对 Zenoh 通用面与实时面、云端桥、媒体 NAT、FTP 与带宽，必要时抓包。 | K29: 未核

Sheet F8 人机界面
A1: 序号 | B1: 测试类 | C1: 需求编号 | D1: 测试功能 | E1: 需求描述（摘自 00） | F1: 测试方法 | G1: 测试结果 | H1: 备注 | I1: 测试人 | J1: 测试时间 | K1: 现状评估（2026-10-29）
A2: 1 | B2: F8 / 12.1 总体 | C2: HMI-01 | D2: 系统提供本地 HMI Web Server，可视化显示机器人作业数据与系统数据 | E2: 系统提供本地 HMI Web Server，可视化显示机器人作业数据与系统数据 | F2: 【真机浏览器】访问 HMI（端口 18083），逐项操作并与云端显示对照。 | K2: 🟡 HMI 服务已在 18083 端口起来，功能未系统测
A3: 2 | B3: F8 / 12.1 总体 | C3: HMI-02 | D3: 显示内容 | E3: 显示内容：RTK/GPS 位置点、航向、多位置点构成的路径、电子围栏、系统运行与作业事件、系统状态、系统故障 | F3: 【真机浏览器】访问 HMI（端口 18083），逐项操作并与云端显示对照。 | K3: 未核
A4: 3 | B4: F8 / 12.1 总体 | C4: HMI-03 | D4: HMI 以只读为主 | E4: 【v0.5 订正】 HMI 以只读为主。可写操作为闭集白名单，当前 5 类（急停 · 点击导航 · 退出喊话 · 任务暂停/取消 · 地理要素改名与删点位）。 每新增一类须重新论证并评审 —— 见 11 §12.1.1「上行 type 白名单规范表（HMI-03 定稿 · 冻结）」，闭集 5 值 ＝ W1 estop · W2 goto · W3 exit_broadcast · W4 geo · W7 task。 【2026-07-30 指针订正】原指 11 §12.3 —— 该节下另有一套 W 编号，是歧义源（同名 §12.3 出现两次：「链路语义与断链行为」与「HMI-03 订正：从两项改为六类」）。 唯一权威闭集只在 §12.1.1；引用本条时不得再指向 §12.3 | F4: 【真机浏览器】访问 HMI（端口 18083），逐项操作并与云端显示对照。 | K4: 未核
A5: 4 | B5: F8 / 12.1 总体 | C5: HMI-03a | D5: 安全约束（电子围栏）与持续驱动（遥控）永不进入 HMI 可写面 | E5: 【v0.5 新增】安全约束（电子围栏）与持续驱动（遥控）永不进入 HMI 可写面。 这是 U23「HMI 不鉴权」成立的前提，不是偏好 —— 白名单极小是它唯一的护栏 | F5: 【真机浏览器】访问 HMI（端口 18083），逐项操作并与云端显示对照。 | K5: 未核
A6: 5 | B6: F8 / 12.1 总体 | C6: HMI-04 | D6: HMI 与云端后台的数据必须来自同一事实来源（同一套事件/状态话题），不得有私有数据通路，否则两端显示会不一致 | E6: 正式需求（ 原【建议】·§0.4a① 结账 2026-07-31） HMI 与云端后台的数据必须来自同一事实来源（同一套事件/状态话题），不得有私有数据通路，否则两端显示会不一致 | F6: 【真机浏览器】访问 HMI（端口 18083），逐项操作并与云端显示对照。 | K6: 未核
A7: 6 | B7: F8 / 12.1 总体 | C7: HMI-05 | D7: 20 Hz 的 RTK 数据推送至 Web 前端需降频（5–10 Hz 足够）+ WebSocket 传输 | E7: 正式需求（ 原【建议】·§0.4a① 结账 2026-07-31） 20 Hz 的 RTK 数据推送至 Web 前端需降频（5–10 Hz 足够）+ WebSocket 传输 | F7: 【真机浏览器】访问 HMI（端口 18083），逐项操作并与云端显示对照。 | K7: 未核
A8: 7 | B8: F8 / 12.1 总体 | C8: HMI-06 | D8: HMI 服务不得影响实时链路，建议轻量实现并限制资源 | E8: 正式需求（ 原【建议】·§0.4a① 结账 2026-07-31） HMI 服务不得影响实时链路，建议轻量实现并限制资源 | F8: 【真机浏览器】访问 HMI（端口 18083），逐项操作并与云端显示对照。 | K8: 未核
A9: 8 | B9: F8 / 12.1 总体 | C9: HMI-07 | D9: 显示当前速度门状态与降速原因（自由空间 / 传感器健康 / RTK 质量），便于现场理解机器人为何减速 | E9: 正式需求（ 原【建议】·§0.4a① 结账 2026-07-31） 显示当前速度门状态与降速原因（自由空间 / 传感器健康 / RTK 质量），便于现场理解机器人为何减速 | F9: 【真机浏览器】访问 HMI（端口 18083），逐项操作并与云端显示对照。 | K9: 未核
A10: 9 | B10: F8 / 12.2 可写操作 | C10: HMI-10 | D10: 点击导航 | E10: 点击导航：在位置点和路径可视化基础上，支持鼠标点击位置点或路径中的任意位置，触发导航至该点 | F10: 【真机浏览器】访问 HMI（端口 18083），逐项操作并与云端显示对照。 | K10: 未核
A11: 10 | B11: F8 / 12.2 可写操作 | C11: HMI-11 | D11: 待确认 | E11: 正式需求（ 原【建议】·§0.4a① 结账 2026-07-31） 待确认：点击点是否必须落在围栏内 / 已有路径上？若不可达如何反馈？是否打断当前任务？相对云端任务的优先级？ | F11: 【真机浏览器】访问 HMI（端口 18083），逐项操作并与云端显示对照。 | K11: 未核
A12: 11 | B12: F8 / 12.2 可写操作 | C12: HMI-20 | D12: 急停 | E12: 急停：支持鼠标点击急停，触发机器人在任何情况下停车，优先级最高，可打断任何任务 | F12: 【真机浏览器】访问 HMI（端口 18083），逐项操作并与云端显示对照。 | K12: 未核
A13: 12 | B13: F8 / 12.2 可写操作 | C13: HMI-21 | D13: 见 NAV-62 ~ NAV-64（专用最短路径直达 Tier 1、硬件急停兜底、链路健康显示） | E13: 正式需求（ 原【建议】·§0.4a① 结账 2026-07-31） 见 NAV-62 ~ NAV-64（专用最短路径直达 Tier 1、硬件急停兜底、链路健康显示） | F13: 【真机浏览器】访问 HMI（端口 18083），逐项操作并与云端显示对照。 | K13: 未核
A14: 13 | B14: F8 / 12.2 可写操作 | C14: HMI-30 | D14: 增加"强制退出广播（B 模式）"按钮，作为 VOI-26 的兜底路径 | E14: 正式需求（ 原【建议】·§0.4a① 结账 2026-07-31） 增加"强制退出广播（B 模式）"按钮，作为 VOI-26 的兜底路径 | F14: 【真机浏览器】访问 HMI（端口 18083），逐项操作并与云端显示对照。 | K14: 未核

Sheet F9 AI与Agent
A1: 序号 | B1: 测试类 | C1: 需求编号 | D1: 测试功能 | E1: 需求描述（摘自 00） | F1: 测试方法 | G1: 测试结果 | H1: 备注 | I1: 测试人 | J1: 测试时间 | K1: 现状评估（2026-10-29）
A2: 1 | B2: F9 / 14.1 AI Runtime 定位 | C2: AI-01 | D2: AI Runtime 由若干 AI 模型推理构成，全部以独立周边服务形式存在 | E2: AI Runtime 由若干 AI 模型推理构成，全部以独立周边服务形式存在 | F2: 【离线 + 真机】离线用生产配置跑 p4 判据（orchestrator）；真机用语音 / 文本验证识别、路由与执行。 | K2: 未核
A3: 2 | B3: F9 / 14.1 AI Runtime 定位 | C3: AI-02 | D3: 服务接口为 OpenAI API 形式 及特有模式 | E3: 服务接口为 OpenAI API 形式 及特有模式 | F3: 【离线 + 真机】离线用生产配置跑 p4 判据（orchestrator）；真机用语音 / 文本验证识别、路由与执行。 | K3: 未核
A4: 3 | B4: F9 / 14.1 AI Runtime 定位 | C4: AI-03 | D4: LLM 为端侧小模型 | E4: LLM 为端侧小模型：llama.cpp / llama-server 运行 qwen2.5-3b-instruct-q4_k_m.gguf，基准推理速度约 26 t/s | F4: 【离线 + 真机】离线用生产配置跑 p4 判据（orchestrator）；真机用语音 / 文本验证识别、路由与执行。 | K4: 未核
A5: 4 | B5: F9 / 14.1 AI Runtime 定位 | C5: AI-04 | D5: 端侧部署保证数据不出设备，符合营区保密要求 | E5: 端侧部署保证数据不出设备，符合营区保密要求 | F5: 【离线 + 真机】离线用生产配置跑 p4 判据（orchestrator）；真机用语音 / 文本验证识别、路由与执行。 | K5: 未核
A6: 5 | B6: F9 / 14.1 AI Runtime 定位 | C6: AI-05 | D6: 该服务化设计合理，V6 予以保留 | E6: 该服务化设计合理，V6 予以保留 | F6: 【离线 + 真机】离线用生产配置跑 p4 判据（orchestrator）；真机用语音 / 文本验证识别、路由与执行。 | K6: 未核
A7: 6 | B7: F9 / 14.2 LLM 在架构中的定位 | C7: AI-10 | D7: LLM 定位为翻译层，而非决策层 | E7: 正式需求（ 原【建议】·§0.4a① 结账 2026-07-31） LLM 定位为翻译层，而非决策层： 入口：自然语言 → 结构化指令 出口：结构化状态 → 自然语言报告 | F7: 【离线 + 真机】离线用生产配置跑 p4 判据（orchestrator）；真机用语音 / 文本验证识别、路由与执行。 | K7: 未核
A8: 7 | B8: F9 / 14.2 LLM 在架构中的定位 | C8: AI-11 | D8: 任务规划主体使用规则 / 状态机 / 行为树（确定性、可测试、可审计），不交由 LLM | E8: 正式需求（ 原【建议】·§0.4a① 结账 2026-07-31） 任务规划主体使用规则 / 状态机 / 行为树（确定性、可测试、可审计），不交由 LLM | F8: 【离线 + 真机】离线用生产配置跑 p4 判据（orchestrator）；真机用语音 / 文本验证识别、路由与执行。 | K8: 未核
A9: 8 | B9: F9 / 14.2 LLM 在架构中的定位 | C9: AI-12 | D9: LLM 失效时机器人仍应能按预定路线完成巡逻（与 NAV-34 一致） | E9: 正式需求（ 原【建议】·§0.4a① 结账 2026-07-31） LLM 失效时机器人仍应能按预定路线完成巡逻（与 NAV-34 一致） | F9: 【离线 + 真机】离线用生产配置跑 p4 判据（orchestrator）；真机用语音 / 文本验证识别、路由与执行。 | K9: 未核
A10: 9 | B10: F9 / 14.3 ASR 后处理 | C10: AI-20 | D10: V5 已实现 | E10: V5 已实现：ASR 推理文本可能有错别字或完全错误的内容，需前处理，主要通过正则纠正易错的 2–5 字短语 | F10: 【离线 + 真机】离线用生产配置跑 p4 判据（orchestrator）；真机用语音 / 文本验证识别、路由与执行。 | K10: ✅ ASR 后处理在真机语音测试中使用（10-24、10-25）
A11: 10 | B11: F9 / 14.3 ASR 后处理 | C11: AI-21 | D11: 改为三层纠错，且纠错规则是数据不是代码 | E11: 正式需求（ 原【建议】·§0.4a① 结账 2026-07-31） 改为三层纠错，且纠错规则是数据不是代码： | F11: 【离线 + 真机】离线用生产配置跑 p4 判据（orchestrator）；真机用语音 / 文本验证识别、路由与执行。 | K11: ✅ ASR 后处理在真机语音测试中使用（10-24、10-25）
A12: 11 | B12: F9 / 14.3 ASR 后处理 | C12: AI-22 | D12: L3 是最有价值的一层，且与 AI-41（LLM 枚举闭集约束）是同一件事的两端 | E12: 正式需求（ 原【建议】·§0.4a① 结账 2026-07-31） L3 是最有价值的一层，且与 AI-41（LLM 枚举闭集约束）是同一件事的两端：ASR 把"东门"识别成"冬门"，L3 直接吸附回合法地名，根本不给 LLM 编造地名的机会。两端都用闭集约束，"编造不存在的位置点"这类最要命的幻觉基本消失 | F12: 【离线 + 真机】离线用生产配置跑 p4 判据（orchestrator）；真机用语音 / 文本验证识别、路由与执行。 | K12: ✅ ASR 后处理在真机语音测试中使用（10-24、10-25）
A13: 12 | B13: F9 / 14.3 ASR 后处理 | C13: AI-23 | D13: 将每次纠错的（原文, 纠正后, 匹配层, 置信度）全部落库，形成持续增长的 ASR 错误语料，用于迭代词典 | E13: 正式需求（ 原【建议】·§0.4a① 结账 2026-07-31） 将每次纠错的（原文, 纠正后, 匹配层, 置信度）全部落库，形成持续增长的 ASR 错误语料，用于迭代词典。现场发现新错误加一行 YAML 热更新，无需改代码重启 | F13: 【离线 + 真机】离线用生产配置跑 p4 判据（orchestrator）；真机用语音 / 文本验证识别、路由与执行。 | K13: ✅ ASR 后处理在真机语音测试中使用（10-24、10-25）
... A43: 42 | B43: F9 / 14.10 计算资源调度 | C43: AI-75 | D43: 上述措施的必要性与强度待实测数据确认，见 §21 | E43: 上述措施的必要性与强度待实测数据确认，见 §21 | F43: 【离线 + 真机】离线用生产配置跑 p4 判据（orchestrator）；真机用语音 / 文本验证识别、路由与执行。 | K43: 未核

Sheet F10 多机
A1: 序号 | B1: 测试类 | C1: 需求编号 | D1: 测试功能 | E1: 需求描述（摘自 00） | F1: 测试方法 | G1: 测试结果 | H1: 备注 | I1: 测试人 | J1: 测试时间 | K1: 现状评估（2026-10-29）
A2: 1 | B2: F10 / 13. 多机与寻址需求（FLT） | C2: FLT-01 | D2: 当前落地为单机器狗，但系统设计必须按机群（狗群）形式设计 | E2: 当前落地为单机器狗，但系统设计必须按机群（狗群）形式设计 | F2: 【审查 + 联调】核对 key 前缀、robot_id 携带与云端按 robot_id 过滤。 | K2: ✅ 单机 gj-001，按机群寻址设计
A3: 2 | B3: F10 / 13. 多机与寻址需求（FLT） | C3: FLT-02 | D3: 所有 Zenoh key、事件、任务、状态消息从第一天起就携带 robot_id | E3: 正式需求（ 原【建议】·§0.4a① 结账 2026-07-31） 所有 Zenoh key、事件、任务、状态消息从第一天起就携带 robot_id。此项若不在设计初期确定，后续需修改全部消息定义 | F3: 【审查 + 联调】核对 key 前缀、robot_id 携带与云端按 robot_id 过滤。 | K3: ✅ key 携带 robot_id
A4: 3 | B4: F10 / 13. 多机与寻址需求（FLT） | C4: FLT-03 | D4: Zenoh key 建议形如 xbrain/{robot_id}/{plane}/{topic} | E4: 正式需求（ 原【建议】·§0.4a① 结账 2026-07-31） Zenoh key 建议形如 xbrain/{robot_id}/{plane}/{topic} | F4: 【审查 + 联调】核对 key 前缀、robot_id 携带与云端按 robot_id 过滤。 | K4: ✅ xbrain/{robot_id}/... 形式
A5: 4 | B5: F10 / 13. 多机与寻址需求（FLT） | C5: FLT-04 | D5: 本期不实现编队协同、任务分配、多机避让，仅保留寻址与身份这一层抽象 | E5: 正式需求（ 原【建议】·§0.4a① 结账 2026-07-31） 本期不实现编队协同、任务分配、多机避让，仅保留寻址与身份这一层抽象。单机跑通优先 | F5: 【审查 + 联调】核对 key 前缀、robot_id 携带与云端按 robot_id 过滤。 | K5: 按需求本期不实现
A6: 5 | B6: F10 / 13. 多机与寻址需求（FLT） | C6: FLT-05 | D6: 云端订阅需支持按 robot_id 过滤与通配 | E6: 正式需求（ 原【建议】·§0.4a① 结账 2026-07-31） 云端订阅需支持按 robot_id 过滤与通配 | F6: 【审查 + 联调】核对 key 前缀、robot_id 携带与云端按 robot_id 过滤。 | K6: 未核

Sheet F11 充电与续航
A1: 序号 | B1: 测试类 | C1: 需求编号 | D1: 测试功能 | E1: 需求描述（摘自 00） | F1: 测试方法 | G1: 测试结果 | H1: 备注 | I1: 测试人 | J1: 测试时间 | K1: 现状评估（2026-10-29）
A2: 1 | B2: F11 / 8.1 充电桩与回桩机制 | C2: CHG-01 | D2: 采用自动回桩充电 | E2: 采用自动回桩充电 | F2: 【真机，需充电桩与 RTK】构造低电 / 选桩场景，核对任务打断、回桩导航、交接点停车与上报、充完恢复。 | K2: ❌ 回桩 / 充电执行未接线（p3 缺 charge 执行器）；选桩等逻辑如有仅单测，真机未测
A3: 2 | B3: F11 / 8.1 充电桩与回桩机制 | C3: CHG-02 | D3: 充电桩设置在巡逻路径上，并标定其 RTK 位置点 | E3: 充电桩设置在巡逻路径上，并标定其 RTK 位置点 | F3: 【真机，需充电桩与 RTK】构造低电 / 选桩场景，核对任务打断、回桩导航、交接点停车与上报、充完恢复。 | K3: ❌ 回桩 / 充电执行未接线（p3 缺 charge 执行器）；选桩等逻辑如有仅单测，真机未测
A4: 3 | B4: F11 / 8.1 充电桩与回桩机制 | C4: CHG-03 | D4: 所有充电桩的 RTK 位置点存入数据库，供选桩计算使用 | E4: 所有充电桩的 RTK 位置点存入数据库，供选桩计算使用 | F4: 【真机，需充电桩与 RTK】构造低电 / 选桩场景，核对任务打断、回桩导航、交接点停车与上报、充完恢复。 | K4: ❌ 回桩 / 充电执行未接线（p3 缺 charge 执行器）；选桩等逻辑如有仅单测，真机未测
A5: 4 | B5: F11 / 8.2 触发条件 | C5: CHG-10 | D5: 电量低于 30% 时打断当前任务，转入回桩充电 | E5: 电量低于 30% 时打断当前任务，转入回桩充电。 【U54 连带 · 2026-07-30】30% 这个数字需要复核 —— 最高速度从 5 m/s 降到 2 m/s 后，同一条 2.5 km 巡逻路径的单圈耗时由 ≈8.3 min 涨到 ≈20.8 min（2.5 倍）。 回桩所需的时间同比拉长，30% 对应的"还能走多远"没变（里程口径），但"还能撑多久"变了 ⇒ 凡按时间口径推导的余量（含现场规程"看到 30% 再叫人"）全部要重算。 数值本身不改，登记为待复核 | F5: 【真机，需充电桩与 RTK】构造低电 / 选桩场景，核对任务打断、回桩导航、交接点停车与上报、充完恢复。 | K5: ❌ 回桩 / 充电执行未接线（p3 缺 charge 执行器）；选桩等逻辑如有仅单测，真机未测
A6: 5 | B6: F11 / 8.2 触发条件 | C6: CHG-11 | D6: 固定阈值不足以覆盖所有情况 —— 30% 够不够取决于最近的桩有多远 | E6: 正式需求（ 原【建议】·§0.4a① 结账 2026-07-31） 固定阈值不足以覆盖所有情况 —— 30% 够不够取决于最近的桩有多远。建议叠加"能量可达性"判据，两者谁先触发算谁： 到最近可达桩的距离 × 安全系数(建议 1.5) > 剩余续航里程 【U54 连带】本判据是里程口径，因此结构上不受降速影响 —— 但它的输入 RemainMile 受影响，见 CHG-12。 15 §5.3 的 V-3 能量可达性判据须按 2 m/s 重算（该文已登记） | F6: 【真机，需充电桩与 RTK】构造低电 / 选桩场景，核对任务打断、回桩导航、交接点停车与上报、充完恢复。 | K6: ❌ 回桩 / 充电执行未接线（p3 缺 charge 执行器）；选桩等逻辑如有仅单测，真机未测
A7: 6 | B7: F11 / 8.2 触发条件 | C7: CHG-12 | D7: 2026-07-28 简化 | E7: 2026-07-28 简化：底盘的运控状态直接提供 RemainMile（预计剩余续航里程 km），可直接用于 CHG-11 的可达性判据，原"实测滑动窗口能耗率"方案作废，无需自行推算。 【2026-07-30 云深处答复引出的新风险】RemainMile 本身依赖当前速度 —— 云深处答它是「基于当前实际耗电数据综合计算」⇒ 反映的是当前速度工况下的剩余里程。 机器人在 obstacle_avoid（0.2–0.5 m/s）低速绕障时，若低速四足的 Wh/km 更差（步态效率 ＋ 姿态维持功耗），估出的 RemainMile 会偏小 ⇒ 不必要的提前回桩。 方向是保守的（安全对），代价是作业时间。 待 T-CHG-2 量化 —— 交叉引用 15 Q-P3-19（勿重复追问） | F7: 【真机，需充电桩与 RTK】构造低电 / 选桩场景，核对任务打断、回桩导航、交接点停车与上报、充完恢复。 | K7: ❌ 回桩 / 充电执行未接线（p3 缺 charge 执行器）；选桩等逻辑如有仅单测，真机未测
A8: 7 | B8: F11 / 8.2 触发条件 | C8: CHG-12b | D8: 双电池 | E8: 双电池：SOC 取左右两块电池 level_pct 的较小值作为触发判据。 【2026-07-30 云深处已答，本条据此补全】：双电池为并联供电；「检测到只有一块电池插入时（PowerManagement::PowerState），robot-server 进入单电池模式，自动降低速度限制」。 连带要求（新）：① 单电池模式必须作为一等状态量上报并进健康度（它会改变速度上限）；② caps.max_vx 是否随之下调尚未答 —— 见 §22 #24 与 15 Q-P3-18；③ 在答复到达前，ETA 与进度预估一律用 state/chassis 回读的实际速度，不得用请求速度 | F8: 【真机，需充电桩与 RTK】构造低电 / 选桩场景，核对任务打断、回桩导航、交接点停车与上报、充完恢复。 | K8: ❌ 回桩 / 充电执行未接线（p3 缺 charge 执行器）；选桩等逻辑如有仅单测，真机未测
A9: 8 | B9: F11 / 8.3 选桩算法 | C9: CHG-20 | D9: 根据当前 RTK 定位与数据库中所有充电桩的 RTK 定位做计算比较，选择顺路且最近的桩 | E9: 根据当前 RTK 定位与数据库中所有充电桩的 RTK 定位做计算比较，选择顺路且最近的桩 | F9: 【真机，需充电桩与 RTK】构造低电 / 选桩场景，核对任务打断、回桩导航、交接点停车与上报、充完恢复。 | K9: ❌ 回桩 / 充电执行未接线（p3 缺 charge 执行器）；选桩等逻辑如有仅单测，真机未测
A10: 9 | B10: F11 / 8.3 选桩算法 | C10: CHG-21 | D10: 顺路的优先级高于距离远近 | E10: 顺路的优先级高于距离远近 | F10: 【真机，需充电桩与 RTK】构造低电 / 选桩场景，核对任务打断、回桩导航、交接点停车与上报、充完恢复。 | K10: ❌ 回桩 / 充电执行未接线（p3 缺 charge 执行器）；选桩等逻辑如有仅单测，真机未测
A11: 10 | B11: F11 / 8.3 选桩算法 | C11: CHG-22 | D11: "顺路"需要可计算的定义 | E11: 正式需求（ 原【建议】·§0.4a① 结账 2026-07-31） "顺路"需要可计算的定义： 投影点 = 桩到「剩余路径」的最近投影 是否顺路 = 投影点在当前位置【前方】 且 侧向偏离 < 阈值 绕行增量 = d(当前→投影点) + d(投影点→桩) − d(当前→投影点) | F11: 【真机，需充电桩与 RTK】构造低电 / 选桩场景，核对任务打断、回桩导航、交接点停车与上报、充完恢复。 | K11: ❌ 回桩 / 充电执行未接线（p3 缺 charge 执行器）；选桩等逻辑如有仅单测，真机未测
A12: 11 | B12: F11 / 8.3 选桩算法 | C12: CHG-23 | D12: 采用三级筛选而非加权打分 | E12: 正式需求（ 原【建议】·§0.4a① 结账 2026-07-31） 采用三级筛选而非加权打分： ① 能量可达性过滤 —— 剔除电量不足以到达的桩 ② 顺路优先 —— 存在顺路桩时只在顺路桩中挑选 ③ 顺路中选最近 —— 无顺路桩时才退化为「全局最近」 理由：CHG-21 是硬优先级，加权打分会出现"权重调整后顺路输给距离"的情况 | F12: 【真机，需充电桩与 RTK】构造低电 / 选桩场景，核对任务打断、回桩导航、交接点停车与上报、充完恢复。 | K12: ❌ 回桩 / 充电执行未接线（p3 缺 charge 执行器）；选桩等逻辑如有仅单测，真机未测
A13: 12 | B13: F11 / 8.4 充电完成与任务恢复 | C13: CHG-30 | D13: 充电完成后重启任务调度 | E13: 充电完成后重启任务调度 | F13: 【真机，需充电桩与 RTK】构造低电 / 选桩场景，核对任务打断、回桩导航、交接点停车与上报、充完恢复。 | K13: ❌ 回桩 / 充电执行未接线（p3 缺 charge 执行器）；选桩等逻辑如有仅单测，真机未测
... A27: 26 | B27: F11 / 8.6 回桩过程的安全约束 | C27: CHG-51 | D27: 已作废 · 本期不做（ §0.4a② —— 被 15 low_batt_profile 缺省 null 取代） | E27: 已作废 · 本期不做（ §0.4a② —— 被 15 low_batt_profile 缺省 null 取代）： 【U54 后本条风险显著上升，已降级为"不做"】 为什么：U54 使可降速幅度从「5 → 2 m/s」变成「2 → 0.5 m/s」（慢 4 倍）—— 四足站立维持功耗在总功耗里的占比被同比放大， 走得更慢很可能反而更耗电（Wh/km 更差），即本条可能适得其反。 本期处置：15 已把 low_batt_profile 缺省改为 disabled（不降速）（ 99 U71：曾写 null，因 null 撞断言 A 订正） —— 不做没有依据的优化。 判据：T-CHG-2 测试点须为 0.2 / 0.5 / 1.0 / 2.0 m/s（ 原写 3 / 5 m/s 已作废），判据是「0.5 m/s 的 Wh/km 是否真的低于 2.0 m/s」。 若不是，本条必须作废。 交叉引用 15 Q-P3-20（P1） | F27: 【真机，需充电桩与 RTK】构造低电 / 选桩场景，核对任务打断、回桩导航、交接点停车与上报、充完恢复。 | K27: 已作废（本期不做）

Sheet F12 开机自检与健康度
A1: 序号 | B1: 测试类 | C1: 需求编号 | D1: 测试功能 | E1: 需求描述（摘自 00） | F1: 测试方法 | G1: 测试结果 | H1: 备注 | I1: 测试人 | J1: 测试时间 | K1: 现状评估（2026-10-29）
A2: 1 | B2: F12 / 9.1 自检范围 | C2: BIT-01 | D2: 每次开机执行开机自检，全部项目仔细自检 | E2: 每次开机执行开机自检，全部项目仔细自检 | F2: 【真机】冷启动观察自检项、分级、放行与播报，核对 health/summary。 | K2: ❌ 快速自检未接线（开机只有问候语）
A3: 2 | B3: F12 / 9.1 自检范围 | C3: BIT-02 | D3: 自检项包含（不限于） | E3: 自检项包含（不限于）： | F3: 【真机】冷启动观察自检项、分级、放行与播报，核对 health/summary。 | K3: ❌ 同上
A4: 3 | B4: F12 / 9.1 自检范围 | C4: BIT-03 | D4: 支持全量自检 TTS 播报，也可配置为部分播报 | E4: 支持全量自检 TTS 播报，也可配置为部分播报 | F4: 【真机】冷启动观察自检项、分级、放行与播报，核对 health/summary。 | K4: ❌ 同上
A5: 4 | B5: F12 / 9.2 自检是健康度系统的初始化 | C5: BIT-10 | D5: 自检不是一次性动作，而是运行时健康度系统的初始状态 | E5: 自检不是一次性动作，而是运行时健康度系统的初始状态： | F5: 【真机】冷启动观察自检项、分级、放行与播报，核对 health/summary。 | K5: 🟡 运行时健康度 health/summary 在发
A6: 5 | B6: F12 / 9.2 自检是健康度系统的初始化 | C6: BIT-11 | D6: 该机制直接提供 NAV-79 所需的 h(传感器健康度) 输入，使"感知降级 → 自动降速"成为闭环 | E6: 该机制直接提供 NAV-79 所需的 h(传感器健康度) 输入，使"感知降级 → 自动降速"成为闭环。自检的数据结构本来就需要存在，因此该项成本几乎为零 | F6: 【真机】冷启动观察自检项、分级、放行与播报，核对 health/summary。 | K6: 🟡 未核
